Workbook

Sheet Inputs
B4: Bar
B5: Rates
B6: Gross Profit Margin | C6: 0.7
B7: Revenue
B8: Avg. cocktail | C8: 18
B9: Avg. Cockatil/person | C9: 2
B10: Avg. spend/customer | C10: =C8*C9 -> 36
B12: Costs
B13: # of bartenders | C13: 2
B14: Bartender/hr | C14: 5
B15: Hostess | C15: 2
B16: Hostess/hr | C16: 15
B19: Barber
B20: Revenue
B21: Avg. spend/customer | C21: 60
B22: % of Barber Rev. Share | C22: 0.5
B24: Income Model | C24: Share
B25: Rent/Chair/Week | C25: 400
B26: Rent/Chair/Day | C26: =C25/7 -> 57.142857
B27: # of Chairs | C27: 6
B28: Weekday Rotations | C28: 3
B29: Weekend Rotations | C29: 10
B30: Weekdays | C30: 4
B31: Weekend Days | C31: 2
B33: Weighted avg. # of Clients/Day | C33: =(($C$27*$C$28)*($C$30/$C$72))+(($C$31/$C$72)*($C$27*$C$29)) -> 32
B35: Avg. Subscription $/Mo | C35: =C21*C36 -> 90
B36: Multiplier | C36: 1.5
B37: # of Subscriptions/Mo | C37: 10
B38: Churn Rate/Yr | C38: 0.02
B41: Costs
B42: # of Barbers | C42: =C27 -> 6
B43: Barber Rev. Share | C43: =1-C22 -> 0.5
B46: Operating Costs
B47: Operating Costs (monthly)
B48: Lease/Mortgage | C48: Lease
B49: Rentable Sqft | C49: 1200
B50: Price/sqft | C50: 50
B51: Lease | C51: =(C49*C50)/12 -> 5000
B52: Mortgage | C52: 0
B53: Utilities | C53: 2000
...

Sheet Projections
G1: 1 | H1: =G1+1 -> 2 | I1: =H1+1 -> 3 | J1: =I1+1 -> 4 | K1: =J1+1 -> 5 | L1: =K1+1 -> 6 | M1: =L1+1 -> 7 | N1: =M1+1 -> 8 | O1: =N1+1 -> 9 | ... Z1: =Y1+1 -> 20
G2: Year 1 | H2: Year 2 | I2: Year 3 | J2: Year 4 | K2: Year 5 | L2: Year 6 | M2: Year 7 | N2: Year 8 | O2: Year 9 | P2: Year 10 | Q2: Year 11 | R2: Year 12 | S2: Year 13 | T2: Year 14 | U2: Year 15 | V2: Year 16 | W2: Year 17 | X2: Year 18 | Y2: Year 19 | Z2: Year 20
B3: Revenue | C3: % of Revenue | D3: Day | E3: Week | F3: Month
B4: Bar | C4: =AVERAGE(G4:K4)/AVERAGE($G$7:$K$7) -> 0.45302536 | D4: =Inputs!C10*Inputs!C71 -> 1620 | E4: =D4*Inputs!$C$72 -> 9720 | F4: =E4*4 -> 38880 | G4: =F4*12 -> 466560 | H4: =G4*(1+IF(H$1<=5,Inputs!$C$79,Inputs!$C$80)) -> 489888 | I4: =H4*(1+IF(I$1<=5,Inputs!$C$79,Inputs!$C$80)) -> 514382.4 | J4: =I4*(1+IF(J$1<=5,Inputs!$C$79,Inputs!$C$80)) -> 540101.52 | K4: =J4*(1+IF(K$1<=5,Inputs!$C$79,Inputs!$C$80)) -> 567106.6 | L4: =K4*(1+IF(L$1<=5,Inputs!$C$79,Inputs!$C$80)) -> 578448.73 | M4: =L4*(1+IF(M$1<=5,Inputs!$C$79,Inputs!$C$80)) -> 590017.7 | N4: =M4*(1+IF(N$1<=5,Inputs!$C$79,Inputs!$C$80)) -> 601818.06 | O4: =N4*(1+IF(O$1<=5,Inputs!$C$79,Inputs!$C$80)) -> 613854.42 | ... Z4: =Y4*(1+IF(Z$1<=5,Inputs!$C$79,Inputs!$C$80)) -> 763250.81
B5: Barber | C5: =AVERAGE(G5:K5)/AVERAGE($G$7:$K$7) -> 0.53691894 | D5: =IF(Inputs!$C$24="Share",(Inputs!$C$33*Inputs!$C$21),Inputs!$C$26*Inputs!$C$27) -> 1920 | E5: =D5*Inputs!$C$72 -> 11520 | F5: =E5*4 -> 46080 | G5: =F5*12 -> 552960 | H5: =G5*(1+IF(H$1<=5,Inputs!$C$79,Inputs!$C$80)) -> 580608 | I5: =H5*(1+IF(I$1<=5,Inputs!$C$79,Inputs!$C$80)) -> 609638.4 | J5: =I5*(1+IF(J$1<=5,Inputs!$C$79,Inputs!$C$80)) -> 640120.32 | K5: =J5*(1+IF(K$1<=5,Inputs!$C$79,Inputs!$C$80)) -> 672126.34 | L5: =K5*(1+IF(L$1<=5,Inputs!$C$79,Inputs!$C$80)) -> 685568.86 | M5: =L5*(1+IF(M$1<=5,Inputs!$C$79,Inputs!$C$80)) -> 699280.24 | N5: =M5*(1+IF(N$1<=5,Inputs!$C$79,Inputs!$C$80)) -> 713265.84 | O5: =N5*(1+IF(O$1<=5,Inputs!$C$79,Inputs!$C$80)) -> 727531.16 | ... Z5: =Y5*(1+IF(Z$1<=5,Inputs!$C$79,Inputs!$C$80)) -> 904593.55
B6: Subscriptions | C6: =AVERAGE(G6:K6)/AVERAGE($G$7:$K$7) -> 0.010055704 | D6: =E6/Inputs!$C$72 -> 37.5 | E6: =F6/4 -> 225 | F6: =Inputs!$C$35*Inputs!C37 -> 900 | G6: =F6*12 -> 10800 | H6: =G6*(1+IF(H$1<=5,Inputs!$C$79,Inputs!$C$80))*(1-Inputs!$C$38) -> 11113.2 | I6: =H6*(1+IF(I$1<=5,Inputs!$C$79,Inputs!$C$80))*(1-Inputs!$C$38) -> 11435.483 | J6: =I6*(1+IF(J$1<=5,Inputs!$C$79,Inputs!$C$80))*(1-Inputs!$C$38) -> 11767.112 | K6: =J6*(1+IF(K$1<=5,Inputs!$C$79,Inputs!$C$80))*(1-Inputs!$C$38) -> 12108.358 | L6: =K6*(1+IF(L$1<=5,Inputs!$C$79,Inputs!$C$80))*(1-Inputs!$C$38) -> 12103.515 | M6: =L6*(1+IF(M$1<=5,Inputs!$C$79,Inputs!$C$80))*(1-Inputs!$C$38) -> 12098.673 | N6: =M6*(1+IF(N$1<=5,Inputs!$C$79,Inputs!$C$80))*(1-Inputs!$C$38) -> 12093.834 | O6: =N6*(1+IF(O$1<=5,Inputs!$C$79,Inputs!$C$80))*(1-Inputs!$C$38) -> 12088.996 | ... Z6: =Y6*(1+IF(Z$1<=5,Inputs!$C$79,Inputs!$C$80))*(1-Inputs!$C$38) -> 12035.911
B7: Total Revenue | C7: =AVERAGE(G7:K7)/AVERAGE($G$7:$K$7) -> 1 | D7: =SUM(D4:D6) -> 3577.5 | E7: =D7*Inputs!$C$72 -> 21465 | F7: =E7*4 -> 85860 | G7: =SUM(G4:G6) -> 1030320 | H7: =SUM(H4:H6) -> 1081609.2 | I7: =SUM(I4:I6) -> 1135456.3 | J7: =SUM(J4:J6) -> 1191989 | K7: =SUM(K4:K6) -> 1251341.3 | L7: =SUM(L4:L6) -> 1276121.1 | M7: =SUM(M4:M6) -> 1301396.6 | N7: =SUM(N4:N6) -> 1327177.7 | ... Z7: =SUM(Z4:Z6) -> 1679880.3
B8: COGS
B9: Bar | C9: =AVERAGE(G9:K9)/AVERAGE($G$7:$K$7) -> 0.13590761 | D9: =D4*(1-Inputs!$C$6) -> 486 | E9: =D9*Inputs!$C$72 -> 2916 | F9: =E9*4 -> 11664 | G9: =F9*12 -> 139968 | H9: =H4*(1-$G15) -> 146966.4 | I9: =I4*(1-$G15) -> 154314.72 | J9: =J4*(1-$G15) -> 162030.46 | K9: =K4*(1-$G15) -> 170131.98 | L9: =L4*(1-$G15) -> 173534.62 | M9: =M4*(1-$G15) -> 177005.31 | N9: =N4*(1-$G15) -> 180545.42 | O9: =O4*(1-$G15) -> 184156.33 | ... Z9: =Z4*(1-$G15) -> 228975.24
B10: Barber | C10: =AVERAGE(G10:K10)/AVERAGE($G$7:$K$7) -> 0.26845947 | D10: =IF(Inputs!$C$24="Share",D5*Inputs!$C$43,0) -> 960 | E10: =D10*Inputs!$C$72 -> 5760 | F10: =E10*4 -> 23040 | G10: =F10*12 -> 276480 | H10: =H5*(1-$G16) -> 290304 | I10: =I5*(1-$G16) -> 304819.2 | J10: =J5*(1-$G16) -> 320060.16 | K10: =K5*(1-$G16) -> 336063.17 | L10: =L5*(1-$G16) -> 342784.43 | M10: =M5*(1-$G16) -> 349640.12 | N10: =N5*(1-$G16) -> 356632.92 | O10: =O5*(1-$G16) -> 363765.58 | ... Z10: =Z5*(1-$G16) -> 452296.78
B11: Subscriptions | C11: =AVERAGE(G11:K11)/AVERAGE($G$7:$K$7) -> 0.005027852 | D11: =D6*Inputs!$C$43 -> 18.75 | E11: =E6*Inputs!$C$43 -> 112.5 | F11: =F6*Inputs!$C$43 -> 450 | G11: =G6*Inputs!$C$43 -> 5400 | H11: =H6*Inputs!$C$43 -> 5556.6 | I11: =I6*Inputs!$C$43 -> 5717.7414 | J11: =J6*Inputs!$C$43 -> 5883.5559 | K11: =K6*Inputs!$C$43 -> 6054.179 | ... Z11: =Z6*Inputs!$C$43 -> 6017.9555
B12: Total COGS | C12: =AVERAGE(G12:K12)/AVERAGE($G$7:$K$7) -> 0.40436708 | D12: =SUM(D9:D10) -> 1446 | E12: =D12*Inputs!$C$72 -> 8676 | F12: =E12*4 -> 34704 | G12: =F12*12 -> 416448 | H12: =SUM(H9:H10) -> 437270.4 | I12: =SUM(I9:I10) -> 459133.92 | J12: =SUM(J9:J10) -> 482090.62 | K12: =SUM(K9:K10) -> 506195.15 | L12: =SUM(L9:L10) -> 516319.05 | M12: =SUM(M9:M10) -> 526645.43 | N12: =SUM(N9:N10) -> 537178.34 | O12: =SUM(O9:O10) -> 547921.91 | ... Z12: =SUM(Z9:Z10) -> 681272.02
B14: Gross Profit | C14: =AVERAGE(G14:K14)/AVERAGE($G$7:$K$7) -> 0.59563292 | D14: =D7-D12 -> 2131.5 | E14: =D14*Inputs!$C$72 -> 12789 | F14: =E14*4 -> 51156 | G14: =G7-G12 -> 613872 | H14: =H7-H12 -> 644338.8 | I14: =I7-I12 -> 676322.36 | J14: =J7-J12 -> 709898.34 | K14: =K7-K12 -> 745146.14 | L14: =L7-L12 -> 759802.06 | M14: =M7-M12 -> 774751.19 | N14: =N7-N12 -> 789999.4 | ... Z14: =Z7-Z12 -> 998608.26
B15: Bar Gross Profit % | D15: =(D4-D9)/D4 -> 0.7 | E15: =(E4-E9)/E4 -> 0.7 | F15: =(F4-F9)/F4 -> 0.7 | G15: =(G4-G9)/G4 -> 0.7 | H15: =(H4-H9)/H4 -> 0.7 | I15: =(I4-I9)/I4 -> 0.7 | J15: =(J4-J9)/J4 -> 0.7 | K15: =(K4-K9)/K4 -> 0.7 | ... Z15: =(Z4-Z9)/Z4 -> 0.7
B16: Barber Gross Profit % | D16: =(D5-D10)/D5 -> 0.5 | E16: =(E5-E10)/E5 -> 0.5 | F16: =(F5-F10)/F5 -> 0.5 | G16: =(G5-G10)/G5 -> 0.5 | H16: =(H5-H10)/H5 -> 0.5 | I16: =(I5-I10)/I5 -> 0.5 | J16: =(J5-J10)/J5 -> 0.5 | K16: =(K5-K10)/K5 -> 0.5 | ... Z16: =(Z5-Z10)/Z5 -> 0.5
B17: Subscriptions Gross Profit % | D17: =(D6-D11)/D6 -> 0.5 | E17: =(E6-E11)/E6 -> 0.5 | F17: =(F6-F11)/F6 -> 0.5 | G17: =(G6-G11)/G6 -> 0.5 | H17: =(H6-H11)/H6 -> 0.5 | I17: =(I6-I11)/I6 -> 0.5 | J17: =(J6-J11)/J6 -> 0.5 | K17: =(K6-K11)/K6 -> 0.5 | ... Z17: =(Z6-Z11)/Z6 -> 0.5
B18: Total Gross Profit % | D18: =D14/D7 -> 0.59580713 | E18: =E14/E7 -> 0.59580713 | F18: =F14/F7 -> 0.59580713 | G18: =G14/G7 -> 0.59580713 | H18: =H14/H7 -> 0.59572237 | I18: =I14/I7 -> 0.59563928 | J18: =J14/J7 -> 0.59555782 | K18: =K14/K7 -> 0.59547795 | ... Z18: =Z14/Z7 -> 0.59445204
B20: Operating Costs
B21: Payroll | C21: =AVERAGE(G21:K21)/AVERAGE($G$7:$K$7) -> 0.06320879 | D21: =((Inputs!$C$13*Inputs!$C$14)+(Inputs!$C$15*Inputs!$C$16))*Inputs!$C$73 -> 240 | E21: =D21*Inputs!$C$72 -> 1440 | F21: =E21*4 -> 5760 | G21: =F21*12 -> 69120 | H21: =G21*(1+Inputs!$C$81) -> 70502.4 | I21: =H21*(1+Inputs!$C$81) -> 71912.448 | J21: =I21*(1+Inputs!$C$81) -> 73350.697 | K21: =J21*(1+Inputs!$C$81) -> 74817.711 | L21: =K21*(1+Inputs!$C$81) -> 76314.065 | M21: =L21*(1+Inputs!$C$81) -> 77840.346 | N21: =M21*(1+Inputs!$C$81) -> 79397.153 | O21: =N21*(1+Inputs!$C$81) -> 80985.096 | ... Z21: =Y21*(1+Inputs!$C$81) -> 100694.79
B22: =Inputs!C48 -> Lease | C22: =AVERAGE(G22:K22)/AVERAGE($G$7:$K$7) -> 0.052717446 | D22: =E22/Inputs!$C$72 -> 208.33333 | E22: =F22/4 -> 1250 | F22: =IF(B22="Mortgage",Inputs!C52,Inputs!C51) -> 5000 | G22: =F22*12 -> 60000 | H22: =G22 -> 60000 | I22: =H22 -> 60000 | J22: =I22 -> 60000 | K22: =J22 -> 60000 | L22: =K22 -> 60000 | M22: =L22 -> 60000 | N22: =M22 -> 60000 | O22: =N22 -> 60000 | ... Z22: =Y22 -> 60000
B23: Property Tax | C23: =AVERAGE(G23:K23)/AVERAGE($G$7:$K$7) -> 0 | D23: =E23/Inputs!$C$72 -> 0 | E23: =F23/4 -> 0 | F23: =IF($B$22="Lease",0,#REF!/12) -> 0 | G23: =F23*12 -> 0 | H23: =G23*(1+Inputs!$C$81) -> 0 | I23: =H23*(1+Inputs!$C$81) -> 0 | J23: =I23*(1+Inputs!$C$81) -> 0 | K23: =J23*(1+Inputs!$C$81) -> 0 | L23: =K23*(1+Inputs!$C$81) -> 0 | M23: =L23*(1+Inputs!$C$81) -> 0 | N23: =M23*(1+Inputs!$C$81) -> 0 | O23: =N23*(1+Inputs!$C$81) -> 0 | ... Z23: =Y23*(1+Inputs!$C$81) -> 0
B24: Utilities | C24: =AVERAGE(G24:K24)/AVERAGE($G$7:$K$7) -> 0.021086978 | D24: =E24/Inputs!$C$72 -> 83.333333 | E24: =F24/4 -> 500 | F24: =Inputs!C53 -> 2000 | G24: =F24*12 -> 24000 | H24: =G24 -> 24000 | I24: =H24 -> 24000 | J24: =I24 -> 24000 | K24: =J24 -> 24000 | L24: =K24 -> 24000 | M24: =L24 -> 24000 | N24: =M24 -> 24000 | O24: =N24 -> 24000 | ... Z24: =Y24 -> 24000
B25: Insurance | C25: =AVERAGE(G25:K25)/AVERAGE($G$7:$K$7) -> 0.0032921245 | D25: =E25/Inputs!$C$72 -> 12.5 | E25: =F25/4 -> 75 | F25: =Inputs!C54 -> 300 | G25: =F25*12 -> 3600 | H25: =G25*(1+Inputs!$C$81) -> 3672 | I25: =H25*(1+Inputs!$C$81) -> 3745.44 | J25: =I25*(1+Inputs!$C$81) -> 3820.3488 | K25: =J25*(1+Inputs!$C$81) -> 3896.7558 | L25: =K25*(1+Inputs!$C$81) -> 3974.6909 | M25: =L25*(1+Inputs!$C$81) -> 4054.1847 | N25: =M25*(1+Inputs!$C$81) -> 4135.2684 | O25: =N25*(1+Inputs!$C$81) -> 4217.9738 | ... Z25: =Y25*(1+Inputs!$C$81) -> 5244.5202
B26: Management fee | C26: =AVERAGE(G26:K26)/AVERAGE($G$7:$K$7) -> 0 | D26: =E26/Inputs!$C$72 -> 0 | E26: =F26/4 -> 0 | F26: =Inputs!C55 -> 0 | G26: =F26*12 -> 0 | H26: =G26*(1+Inputs!$C$79) -> 0 | I26: =H26*(1+Inputs!$C$79) -> 0 | J26: =I26*(1+Inputs!$C$79) -> 0 | K26: =J26*(1+Inputs!$C$79) -> 0 | L26: =K26*(1+Inputs!$C$79) -> 0 | M26: =L26*(1+Inputs!$C$79) -> 0 | N26: =M26*(1+Inputs!$C$79) -> 0 | O26: =N26*(1+Inputs!$C$79) -> 0 | ... Z26: =Y26*(1+Inputs!$C$79) -> 0
B27: Other | C27: =AVERAGE(G27:K27)/AVERAGE($G$7:$K$7) -> 0.021086978 | D27: =E27/Inputs!$C$72 -> 83.333333 | E27: =F27/4 -> 500 | F27: =Inputs!C56 -> 2000 | G27: =F27*12 -> 24000 | H27: =G27 -> 24000 | I27: =H27 -> 24000 | J27: =I27 -> 24000 | K27: =J27 -> 24000 | L27: =K27 -> 24000 | M27: =L27 -> 24000 | N27: =M27 -> 24000 | O27: =N27 -> 24000 | ... Z27: =Y27 -> 24000
B28: Total Operating Costs | C28: =AVERAGE(G28:K28)/AVERAGE($G$7:$K$7) -> 0.16139232 | D28: =SUM(D21:D27) -> 627.5 | E28: =SUM(E21:E27) -> 3765 | F28: =SUM(F21:F27) -> 15060 | G28: =SUM(G21:G27) -> 180720 | H28: =SUM(H21:H27) -> 182174.4 | I28: =SUM(I21:I27) -> 183657.89 | J28: =SUM(J21:J27) -> 185171.05 | K28: =SUM(K21:K27) -> 186714.47 | ... Z28: =SUM(Z21:Z27) -> 213939.31
B30: Operating Profit | C30: =AVERAGE(G30:K30)/AVERAGE($G$7:$K$7) -> 0.43424061 | D30: =D14-D28 -> 1504 | E30: =E14-E28 -> 9024 | F30: =F14-F28 -> 36096 | G30: =G14-G28 -> 433152 | H30: =H14-H28 -> 462164.4 | I30: =I14-I28 -> 492664.47 | J30: =J14-J28 -> 524727.29 | K30: =K14-K28 -> 558431.68 | ... Z30: =Z14-Z28 -> 784668.95
B31: Operating Profit Margin | D31: =D30/D7 -> 0.42040531 | E31: =E30/E7 -> 0.42040531 | F31: =F30/F7 -> 0.42040531 | G31: =G30/G7 -> 0.42040531 | H31: =H30/H7 -> 0.42729333 | I31: =I30/I7 -> 0.43389119 | J31: =J30/J7 -> 0.44021154 | K31: =K30/K7 -> 0.44626648 | ... Z31: =Z30/Z7 -> 0.46709814
B32: Taxes
B33: Expected taxes | C33: =AVERAGE(G33:K33)/AVERAGE($G$7:$K$7) -> 0.13461459 | D33: =IF(D30<0,0,D30*Inputs!$C$76) -> 466.24 | E33: =IF(E30<0,0,E30*Inputs!$C$76) -> 2797.44 | F33: =IF(F30<0,0,F30*Inputs!$C$76) -> 11189.76 | G33: =IF(G30<0,0,G30*Inputs!$C$76) -> 134277.12 | H33: =IF(H30<0,0,H30*Inputs!$C$76) -> 143270.96 | I33: =IF(I30<0,0,I30*Inputs!$C$76) -> 152725.99 | J33: =IF(J30<0,0,J30*Inputs!$C$76) -> 162665.46 | K33: =IF(K30<0,0,K30*Inputs!$C$76) -> 173113.82 | ... Z33: =IF(Z30<0,0,Z30*Inputs!$C$76) -> 243247.37
B34: Net Income | C34: =AVERAGE(G34:K34)/AVERAGE($G$7:$K$7) -> 0.29962602 | D34: =D30-D33 -> 1037.76 | E34: =E30-E33 -> 6226.56 | F34: =F30-F33 -> 24906.24 | G34: =G30-G33 -> 298874.88 | H34: =H30-H33 -> 318893.44 | I34: =I30-I33 -> 339938.49 | J34: =J30-J33 -> 362061.83 | K34: =K30-K33 -> 385317.86 | ... Z34: =Z30-Z33 -> 541421.57
B35: Net Income % | D35: =D34/D7 -> 0.29007966 | E35: =E34/E7 -> 0.29007966 | F35: =F34/F7 -> 0.29007966 | G35: =G34/G7 -> 0.29007966 | H35: =H34/H7 -> 0.2948324 | I35: =I34/I7 -> 0.29938492 | J35: =J34/J7 -> 0.30374596 | K35: =K34/K7 -> 0.30792387 | ... Z35: =Z34/Z7 -> 0.32229771
B37: ="Reinvestment "&"("&Inputs!$C$57*100&"%)" -> Reinvestment (10%) | C37: =AVERAGE(G37:K37)/AVERAGE($G$7:$K$7) -> 0.029962602 | D37: =IF(D34<0,0,Inputs!$C$57*D30) -> 150.4 | E37: =IF(E34<0,0,Inputs!$C$57*E30) -> 902.4 | F37: =IF(F34<0,0,Inputs!$C$57*F30) -> 3609.6 | G37: =IF(G34<0,0,Inputs!$C$57*G34) -> 29887.488 | H37: =IF(H34<0,0,Inputs!$C$57*H34) -> 31889.344 | I37: =IF(I34<0,0,Inputs!$C$57*I34) -> 33993.849 | J37: =IF(J34<0,0,Inputs!$C$57*J34) -> 36206.183 | K37: =IF(K34<0,0,Inputs!$C$57*K34) -> 38531.786 | L37: =IF(L34<0,0,Inputs!$C$57*L34) -> 39434.418 | M37: =IF(M34<0,0,Inputs!$C$57*M34) -> 40355.109 | N37: =IF(N34<0,0,Inputs!$C$57*N34) -> 41294.221 | ... Z37: =IF(Z34<0,0,Inputs!$C$57*Z34) -> 54142.157
B38: Cash Avilable for Distribution | C38: =AVERAGE(G38:K38)/AVERAGE($G$7:$K$7) -> 0.26966342 | D38: =D34-D37 -> 887.36 | E38: =E34-E37 -> 5324.16 | F38: =F34-F37 -> 21296.64 | G38: =G34-G37 -> 268987.39 | H38: =H34-H37 -> 287004.09 | I38: =I34-I37 -> 305944.64 | J38: =J34-J37 -> 325855.65 | K38: =K34-K37 -> 346786.07 | ... Z38: =Z34-Z37 -> 487279.42
G57: Yr | H57: Mo | I57: night
B58: Revenue/seat | C58: =AVERAGE(G7:K7)/(Inputs!$C$71*Inputs!$C$72*4*12) -> 87.819687 | F58: Avg. Rev | G58: =AVERAGE(G7:K7) -> 1138143.1 | H58: =G58/12 -> 94845.262 | I58: =H58/Inputs!$C$74 -> 3161.5087
B59: Rev./sqft | C59: =AVERAGE(G7:K7)/Inputs!$C$62 -> 948.45262 | F59: Avg. Var. Costs | G59: =AVERAGE(G12:K12) -> 460227.62 | H59: =G59/12 -> 38352.301 | I59: =H59/Inputs!$C$74 -> 1278.41
B60: RevPASH | C60: =AVERAGE($G$7:$K$7)/((Inputs!$C$73*Inputs!$C$67)*Inputs!$C$74*12) -> 8.7819687
B61: Prime Cost Ratio | C61: =((AVERAGE(G12:K12)+AVERAGE(G21:K21))/AVERAGE($G$7:$K$7)) -> 0.46757587 | F61: Average. Fixed | G61: =AVERAGE(G28:K28) -> 183687.56 | H61: =G61/12 -> 15307.297 | I61: =H61/Inputs!$C$74 -> 510.24322
B62: Break-Even Point | C62: =(I61/((I58-I59)/I58)) -> 856.64039
...
