Workbook
Name Cash_Minimum: 'Cash flow forecast'!#REF!
Name Start_Date: 'Cash flow forecast'!#REF!

Sheet Assumptions
A1: *Note: all dates in the assumptions tab must start on the 1st
A2: Model Start Date | B2: 45809
A3: Select Sheet Quality Costs | B3: TC250
A4: Unit Inputs
A6: Products
B7: Price/Unit | C7: Cost/Unit | D7: $ Mark up | E7: Mark up%
A8: Twin Package:
A9: Twin Top Sheet | B9: =C9*(1+$E9) -> 7.71 | C9: =INDEX('Unit Costs'!$C$5:$C$42,MATCH(Assumptions!$A9,'Unit Costs'!$B$5:$B$42,0)) -> 5.14 | D9: =B9-C9 -> 2.57 | E9: 0.5
A10: Twin Bottom Sheet | B10: =C10*(1+$E10) -> 0 | C10: =INDEX('Unit Costs'!$C$5:$C$42,MATCH(Assumptions!$A10,'Unit Costs'!$B$5:$B$42,0)) -> 0 | D10: =B10-C10 -> 0 | E10: 0.5
A11: Twin Decorative Sheet | B11: =C11*(1+$E11) -> 9.225 | C11: =INDEX('Unit Costs'!$C$5:$C$42,MATCH(Assumptions!$A11,'Unit Costs'!$B$5:$B$42,0)) -> 6.15 | D11: =B11-C11 -> 3.075 | E11: 0.5
A12: Twin Fitted Sheet | B12: =C12*(1+$E12) -> 8.76 | C12: =INDEX('Unit Costs'!$C$5:$C$42,MATCH(Assumptions!$A12,'Unit Costs'!$B$5:$B$42,0)) -> 5.84 | D12: =B12-C12 -> 2.92 | E12: 0.5
A13: Std Pillow Case | B13: =C13*(1+$E13) -> 1.71 | C13: =INDEX('Unit Costs'!$C$5:$C$42,MATCH(Assumptions!$A13,'Unit Costs'!$B$5:$B$42,0)) -> 1.14 | D13: =B13-C13 -> 0.57 | E13: 0.5
A14: Total Twin | B14: =SUM(B9:B13) -> 27.405 | C14: =SUM(C9:C13) -> 18.27 | D14: =SUM(D9:D13) -> 9.135 | E14: =D14/C14 -> 0.5
A16: Full Package:
A17: Full Top Sheet | B17: =C17*(1+$E17) -> 6 | C17: =INDEX('Unit Costs'!$C$5:$C$42,MATCH(Assumptions!$A17,'Unit Costs'!$B$5:$B$42,0)) -> 4 | D17: =B17-C17 -> 2 | E17: 0.5
A18: Full Bottom Sheet | B18: =C18*(1+$E18) -> 0 | C18: =INDEX('Unit Costs'!$C$5:$C$42,MATCH(Assumptions!$A18,'Unit Costs'!$B$5:$B$42,0)) -> 0 | D18: =B18-C18 -> 0 | E18: 0.5
A19: Full Decorative Sheet | B19: =C19*(1+$E19) -> 10.5 | C19: =INDEX('Unit Costs'!$C$5:$C$42,MATCH(Assumptions!$A19,'Unit Costs'!$B$5:$B$42,0)) -> 7 | D19: =B19-C19 -> 3.5 | E19: 0.5
A20: Full Fitted Sheet | B20: =C20*(1+$E20) -> 4.5 | C20: =INDEX('Unit Costs'!$C$5:$C$42,MATCH(Assumptions!$A20,'Unit Costs'!$B$5:$B$42,0)) -> 3 | D20: =B20-C20 -> 1.5 | E20: 0.5
A21: Std Pillow Case | B21: =C21*(1+$E21) -> 1.71 | C21: =INDEX('Unit Costs'!$C$5:$C$42,MATCH(Assumptions!$A21,'Unit Costs'!$B$5:$B$42,0)) -> 1.14 | D21: =B21-C21 -> 0.57 | E21: 0.5
A22: Total Full | B22: =SUM(B17:B21) -> 22.71 | C22: =SUM(C17:C21) -> 15.14 | D22: =SUM(D17:D21) -> 7.57 | E22: =D22/C22 -> 0.5
A24: Queen Package:
A25: Queen Top (Flat) Sheet | B25: =C25*(1+$E25) -> 13.5 | C25: =INDEX('Unit Costs'!$C$5:$C$42,MATCH(Assumptions!$A25,'Unit Costs'!$B$5:$B$42,0)) -> 9 | D25: =B25-C25 -> 4.5 | E25: 0.5
A26: Queen Bottom (fitted 2.0) Sheet | B26: =C26*(1+$E26) -> 0 | C26: =INDEX('Unit Costs'!$C$5:$C$42,MATCH(Assumptions!$A26,'Unit Costs'!$B$5:$B$42,0)) -> 0 | D26: =B26-C26 -> 0 | E26: 0.5
A27: Queen Decorative Sheet | B27: =C27*(1+$E27) -> 10.5 | C27: =INDEX('Unit Costs'!$C$5:$C$42,MATCH(Assumptions!$A27,'Unit Costs'!$B$5:$B$42,0)) -> 7 | D27: =B27-C27 -> 3.5 | E27: 0.5
A28: Queen Fitted Sheet | B28: =C28*(1+$E28) -> 10.5 | C28: =INDEX('Unit Costs'!$C$5:$C$42,MATCH(Assumptions!$A28,'Unit Costs'!$B$5:$B$42,0)) -> 7 | D28: =B28-C28 -> 3.5 | E28: 0.5
A29: Queen Pillow Case | B29: =C29*(1+$E29) -> 4.5 | C29: =INDEX('Unit Costs'!$C$5:$C$42,MATCH(Assumptions!$A29,'Unit Costs'!$B$5:$B$42,0)) -> 3 | D29: =B29-C29 -> 1.5 | E29: 0.5
A30: Total Queen | B30: =SUM(B25:B29) -> 39 | C30: =SUM(C25:C29) -> 26 | D30: =SUM(D25:D29) -> 13 | E30: =D30/C30 -> 0.5
A32: King Package:
A33: King Top Sheet | B33: =C33*(1+$E33) -> 15 | C33: =INDEX('Unit Costs'!$C$5:$C$42,MATCH(Assumptions!$A33,'Unit Costs'!$B$5:$B$42,0)) -> 10 | D33: =B33-C33 -> 5 | E33: 0.5
A34: King Bottom Sheet | B34: =C34*(1+$E34) -> 0 | C34: =INDEX('Unit Costs'!$C$5:$C$42,MATCH(Assumptions!$A34,'Unit Costs'!$B$5:$B$42,0)) -> 0 | D34: =B34-C34 -> 0 | E34: 0.5
A35: King Decor Sheet | B35: =C35*(1+$E35) -> 10.5 | C35: =INDEX('Unit Costs'!$C$5:$C$42,MATCH(Assumptions!$A35,'Unit Costs'!$B$5:$B$42,0)) -> 7 | D35: =B35-C35 -> 3.5 | E35: 0.5
A36: King Fitted Sheet | B36: =C36*(1+$E36) -> 13.5 | C36: =INDEX('Unit Costs'!$C$5:$C$42,MATCH(Assumptions!$A36,'Unit Costs'!$B$5:$B$42,0)) -> 9 | D36: =B36-C36 -> 4.5 | E36: 0.5
A37: King Pillow Case | B37: =C37*(1+$E37) -> 12 | C37: =INDEX('Unit Costs'!$C$5:$C$42,MATCH(Assumptions!$A37,'Unit Costs'!$B$5:$B$42,0)) -> 8 | D37: =B37-C37 -> 4 | E37: 0.5
A38: Total King | B38: =SUM(B33:B37) -> 51 | C38: =SUM(C33:C37) -> 34 | D38: =SUM(D33:D37) -> 17 | E38: =D38/C38 -> 0.5
A40: Universal Package:
A41: Universal Top Sheet | B41: =C41*(1+$E41) -> 13.065 | C41: =INDEX('Unit Costs'!$C$5:$C$42,MATCH(Assumptions!$A41,'Unit Costs'!$B$5:$B$42,0)) -> 8.71 | D41: =B41-C41 -> 4.355 | E41: 0.5
A42: Universal Bottom Sheet | B42: =C42*(1+$E42) -> 0 | C42: =INDEX('Unit Costs'!$C$5:$C$42,MATCH(Assumptions!$A42,'Unit Costs'!$B$5:$B$42,0)) -> 0 | D42: =B42-C42 -> 0 | E42: 0.5
A43: Universal Decor Sheet | B43: =C43*(1+$E43) -> 0 | C43: =INDEX('Unit Costs'!$C$5:$C$42,MATCH(Assumptions!$A43,'Unit Costs'!$B$5:$B$42,0)) -> 0 | D43: =B43-C43 -> 0 | E43: 0.5
A44: Universal Fitted Sheet | B44: =C44*(1+$E44) -> 0 | C44: =INDEX('Unit Costs'!$C$5:$C$42,MATCH(Assumptions!$A44,'Unit Costs'!$B$5:$B$42,0)) -> 0 | D44: =B44-C44 -> 0 | E44: 0.5
A45: Universal Pillow Case | B45: =C45*(1+$E45) -> 0 | C45: =INDEX('Unit Costs'!$C$5:$C$42,MATCH(Assumptions!$A45,'Unit Costs'!$B$5:$B$42,0)) -> 0 | D45: =B45-C45 -> 0 | E45: 0.5
...

Sheet Cash flow forecast
B1: NeetSheets
B2: Cash Flow Forecast
C3: =YEAR(C5) -> 2025 | D3: =YEAR(D5) -> 2025 | E3: =YEAR(E5) -> 2025 | F3: =YEAR(F5) -> 2025 | G3: =YEAR(G5) -> 2025 | H3: =YEAR(H5) -> 2025 | I3: =YEAR(I5) -> 2025 | J3: =YEAR(J5) -> 2026 | ... Z3: =YEAR(Z5) -> 2027
C4: 1 | D4: =C4+1 -> 2 | E4: =D4+1 -> 3 | F4: =E4+1 -> 4 | G4: =F4+1 -> 5 | H4: =G4+1 -> 6 | I4: =H4+1 -> 7 | J4: =I4+1 -> 8 | K4: =J4+1 -> 9 | ... N4: =M4+1 -> 12 | O4: 1 | P4: =O4+1 -> 2 | Q4: =P4+1 -> 3 | R4: =Q4+1 -> 4 | S4: =R4+1 -> 5 | T4: =S4+1 -> 6 | U4: =T4+1 -> 7 | V4: =U4+1 -> 8 | W4: =V4+1 -> 9 | ... Z4: =Y4+1 -> 12
C5: =Assumptions!$B$2 -> 45809 | D5: =EDATE(C5,1) -> 45839 | E5: =EDATE(D5,1) -> 45870 | F5: =EDATE(E5,1) -> 45901 | G5: =EDATE(F5,1) -> 45931 | H5: =EDATE(G5,1) -> 45962 | I5: =EDATE(H5,1) -> 45992 | J5: =EDATE(I5,1) -> 46023 | K5: =EDATE(J5,1) -> 46054 | ... Z5: =EDATE(Y5,1) -> 46508 | AA5: =$C$6 -> Q2 | AB5: =IF(RIGHT(AA$5,1)="4","Q1","Q"&RIGHT(AA5,1)+1) -> Q3 | AC5: =IF(RIGHT(AB$5,1)="4","Q1","Q"&RIGHT(AB5,1)+1) -> Q4 | AD5: =IF(RIGHT(AC$5,1)="4","Q1","Q"&RIGHT(AC5,1)+1) -> Q1 | AE5: Trailing 12 Month | AF5: =$O$6 -> Q2 | AG5: =IF(RIGHT(AF$5,1)="4","Q1","Q"&RIGHT(AF5,1)+1) -> Q3 | AH5: =IF(RIGHT(AG$5,1)="4","Q1","Q"&RIGHT(AG5,1)+1) -> Q4 | AI5: =IF(RIGHT(AH$5,1)="4","Q1","Q"&RIGHT(AH5,1)+1) -> Q1 | AJ5: Trailing 12 Month
C6: =INDEX(Formatting!$B$2:$B$13,MATCH(MONTH('Cash flow forecast'!C$5),Formatting!$C$2:$C$13,0)) -> Q2 | D6: =INDEX(Formatting!$B$2:$B$13,MATCH(MONTH('Cash flow forecast'!D$5),Formatting!$C$2:$C$13,0)) -> Q3 | E6: =INDEX(Formatting!$B$2:$B$13,MATCH(MONTH('Cash flow forecast'!E$5),Formatting!$C$2:$C$13,0)) -> Q3 | F6: =INDEX(Formatting!$B$2:$B$13,MATCH(MONTH('Cash flow forecast'!F$5),Formatting!$C$2:$C$13,0)) -> Q3 | G6: =INDEX(Formatting!$B$2:$B$13,MATCH(MONTH('Cash flow forecast'!G$5),Formatting!$C$2:$C$13,0)) -> Q4 | H6: =INDEX(Formatting!$B$2:$B$13,MATCH(MONTH('Cash flow forecast'!H$5),Formatting!$C$2:$C$13,0)) -> Q4 | I6: =INDEX(Formatting!$B$2:$B$13,MATCH(MONTH('Cash flow forecast'!I$5),Formatting!$C$2:$C$13,0)) -> Q4 | J6: =INDEX(Formatting!$B$2:$B$13,MATCH(MONTH('Cash flow forecast'!J$5),Formatting!$C$2:$C$13,0)) -> Q1 | ... Z6: =INDEX(Formatting!$B$2:$B$13,MATCH(MONTH('Cash flow forecast'!Z$5),Formatting!$C$2:$C$13,0)) -> Q2 | AA6: =INDEX($C$3:$N$3,MATCH(AA$5,$C$6:$N$6,0)) -> 2025 | AB6: =INDEX($C$3:$N$3,MATCH(AB$5,$C$6:$N$6,0)) -> 2025 | AC6: =INDEX($C$3:$N$3,MATCH(AC$5,$C$6:$N$6,0)) -> 2025 | AD6: =INDEX($C$3:$N$3,MATCH(AD$5,$C$6:$N$6,0)) -> 2026 | AF6: =INDEX($O$3:$Z$3,MATCH(AF$5,$O$6:$Z$6,0)) -> 2026 | AG6: =INDEX($O$3:$Z$3,MATCH(AG$5,$O$6:$Z$6,0)) -> 2026 | AH6: =INDEX($O$3:$Z$3,MATCH(AH$5,$O$6:$Z$6,0)) -> 2026 | AI6: =INDEX($O$3:$Z$3,MATCH(AI$5,$O$6:$Z$6,0)) -> 2027
B7: Revenue
B8: Wholesale Revenue: | AK8: Annual % of Revenue
B9: Small Hotels
B10: # of New Hotels | C10: =SUMIFS(Formatting!$A$23:$A$27,Formatting!$E$23:$E$27,'Cash flow forecast'!C$5) -> 5 | D10: =SUMIFS(Formatting!$A$23:$A$27,Formatting!$E$23:$E$27,'Cash flow forecast'!D$5) -> 0 | E10: =SUMIFS(Formatting!$A$23:$A$27,Formatting!$E$23:$E$27,'Cash flow forecast'!E$5) -> 2 | F10: =SUMIFS(Formatting!$A$23:$A$27,Formatting!$E$23:$E$27,'Cash flow forecast'!F$5) -> 0 | G10: =SUMIFS(Formatting!$A$23:$A$27,Formatting!$E$23:$E$27,'Cash flow forecast'!G$5) -> 0 | H10: =SUMIFS(Formatting!$A$23:$A$27,Formatting!$E$23:$E$27,'Cash flow forecast'!H$5) -> 0 | I10: =SUMIFS(Formatting!$A$23:$A$27,Formatting!$E$23:$E$27,'Cash flow forecast'!I$5) -> 0 | J10: =SUMIFS(Formatting!$A$23:$A$27,Formatting!$E$23:$E$27,'Cash flow forecast'!J$5) -> 0 | ... Z10: =SUMIFS(Formatting!$A$23:$A$27,Formatting!$E$23:$E$27,'Cash flow forecast'!Z$5) -> 0
B11: # of Renew Orders | C11: =IFERROR(INDEX(Formatting!$F$24:$T$24,MATCH('Cash flow forecast'!C$5,Formatting!$F$23:$T$23,0)),0)+IFERROR(INDEX(Formatting!$F$26:$T$26,MATCH('Cash flow forecast'!C$5,Formatting!$F$25:$T$25,0)),0)+IFERROR(INDEX(Formatting!$F$28:$T$28,MATCH('Cash flow forecast'!C$5,Formatting!$F$27:$T$27,0)),0) -> 0 | D11: =IFERROR(INDEX(Formatting!$F$24:$T$24,MATCH('Cash flow forecast'!D$5,Formatting!$F$23:$T$23,0)),0)+IFERROR(INDEX(Formatting!$F$26:$T$26,MATCH('Cash flow forecast'!D$5,Formatting!$F$25:$T$25,0)),0)+IFERROR(INDEX(Formatting!$F$28:$T$28,MATCH('Cash flow forecast'!D$5,Formatting!$F$27:$T$27,0)),0) -> 0 | E11: =IFERROR(INDEX(Formatting!$F$24:$T$24,MATCH('Cash flow forecast'!E$5,Formatting!$F$23:$T$23,0)),0)+IFERROR(INDEX(Formatting!$F$26:$T$26,MATCH('Cash flow forecast'!E$5,Formatting!$F$25:$T$25,0)),0)+IFERROR(INDEX(Formatting!$F$28:$T$28,MATCH('Cash flow forecast'!E$5,Formatting!$F$27:$T$27,0)),0) -> 0 | F11: =IFERROR(INDEX(Formatting!$F$24:$T$24,MATCH('Cash flow forecast'!F$5,Formatting!$F$23:$T$23,0)),0)+IFERROR(INDEX(Formatting!$F$26:$T$26,MATCH('Cash flow forecast'!F$5,Formatting!$F$25:$T$25,0)),0)+IFERROR(INDEX(Formatting!$F$28:$T$28,MATCH('Cash flow forecast'!F$5,Formatting!$F$27:$T$27,0)),0) -> 0 | G11: =IFERROR(INDEX(Formatting!$F$24:$T$24,MATCH('Cash flow forecast'!G$5,Formatting!$F$23:$T$23,0)),0)+IFERROR(INDEX(Formatting!$F$26:$T$26,MATCH('Cash flow forecast'!G$5,Formatting!$F$25:$T$25,0)),0)+IFERROR(INDEX(Formatting!$F$28:$T$28,MATCH('Cash flow forecast'!G$5,Formatting!$F$27:$T$27,0)),0) -> 0 | H11: =IFERROR(INDEX(Formatting!$F$24:$T$24,MATCH('Cash flow forecast'!H$5,Formatting!$F$23:$T$23,0)),0)+IFERROR(INDEX(Formatting!$F$26:$T$26,MATCH('Cash flow forecast'!H$5,Formatting!$F$25:$T$25,0)),0)+IFERROR(INDEX(Formatting!$F$28:$T$28,MATCH('Cash flow forecast'!H$5,Formatting!$F$27:$T$27,0)),0) -> 0 | I11: =IFERROR(INDEX(Formatting!$F$24:$T$24,MATCH('Cash flow forecast'!I$5,Formatting!$F$23:$T$23,0)),0)+IFERROR(INDEX(Formatting!$F$26:$T$26,MATCH('Cash flow forecast'!I$5,Formatting!$F$25:$T$25,0)),0)+IFERROR(INDEX(Formatting!$F$28:$T$28,MATCH('Cash flow forecast'!I$5,Formatting!$F$27:$T$27,0)),0) -> 5 | J11: =IFERROR(INDEX(Formatting!$F$24:$T$24,MATCH('Cash flow forecast'!J$5,Formatting!$F$23:$T$23,0)),0)+IFERROR(INDEX(Formatting!$F$26:$T$26,MATCH('Cash flow forecast'!J$5,Formatting!$F$25:$T$25,0)),0)+IFERROR(INDEX(Formatting!$F$28:$T$28,MATCH('Cash flow forecast'!J$5,Formatting!$F$27:$T$27,0)),0) -> 0 | ... Z11: =IFERROR(INDEX(Formatting!$F$24:$T$24,MATCH('Cash flow forecast'!Z$5,Formatting!$F$23:$T$23,0)),0)+IFERROR(INDEX(Formatting!$F$26:$T$26,MATCH('Cash flow forecast'!Z$5,Formatting!$F$25:$T$25,0)),0)+IFERROR(INDEX(Formatting!$F$28:$T$28,MATCH('Cash flow forecast'!Z$5,Formatting!$F$27:$T$27,0)),0) -> 0
B12: Twin Package Orders | C12: =((INDEX(Assumptions!$B$8:$B$46,MATCH("Total Twin",Assumptions!$A$8:$A$46,0)))*((C$10+C$11)*INDEX(Assumptions!$E$60:$E$65,MATCH('Cash flow forecast'!$B12,Assumptions!$A$60:$A$65,0)))) -> 10276.875 | D12: =(((INDEX(Assumptions!$B$8:$B$46,MATCH("Total Twin",Assumptions!$A$8:$A$46,0)))*((D$10+D$11)*INDEX(Assumptions!$E$60:$E$65,MATCH('Cash flow forecast'!$B12,Assumptions!$A$60:$A$65,0)))))*(1+Assumptions!$B$67) -> 0 | E12: =(((INDEX(Assumptions!$B$8:$B$46,MATCH("Total Twin",Assumptions!$A$8:$A$46,0)))*((E$10+E$11)*INDEX(Assumptions!$E$60:$E$65,MATCH('Cash flow forecast'!$B12,Assumptions!$A$60:$A$65,0)))))*(1+Assumptions!$B$67) -> 3699.675 | F12: =(((INDEX(Assumptions!$B$8:$B$46,MATCH("Total Twin",Assumptions!$A$8:$A$46,0)))*((F$10+F$11)*INDEX(Assumptions!$E$60:$E$65,MATCH('Cash flow forecast'!$B12,Assumptions!$A$60:$A$65,0)))))*(1+Assumptions!$B$67) -> 0 | G12: =(((INDEX(Assumptions!$B$8:$B$46,MATCH("Total Twin",Assumptions!$A$8:$A$46,0)))*((G$10+G$11)*INDEX(Assumptions!$E$60:$E$65,MATCH('Cash flow forecast'!$B12,Assumptions!$A$60:$A$65,0)))))*(1+Assumptions!$B$67) -> 0 | H12: =(((INDEX(Assumptions!$B$8:$B$46,MATCH("Total Twin",Assumptions!$A$8:$A$46,0)))*((H$10+H$11)*INDEX(Assumptions!$E$60:$E$65,MATCH('Cash flow forecast'!$B12,Assumptions!$A$60:$A$65,0)))))*(1+Assumptions!$B$67) -> 0 | I12: =(((INDEX(Assumptions!$B$8:$B$46,MATCH("Total Twin",Assumptions!$A$8:$A$46,0)))*((I$10+I$11)*INDEX(Assumptions!$E$60:$E$65,MATCH('Cash flow forecast'!$B12,Assumptions!$A$60:$A$65,0)))))*(1+Assumptions!$B$67) -> 9249.1875 | J12: =(((INDEX(Assumptions!$B$8:$B$46,MATCH("Total Twin",Assumptions!$A$8:$A$46,0)))*((J$10+J$11)*INDEX(Assumptions!$E$60:$E$65,MATCH('Cash flow forecast'!$B12,Assumptions!$A$60:$A$65,0)))))*(1+Assumptions!$B$67) -> 0 | K12: =(((INDEX(Assumptions!$B$8:$B$46,MATCH("Total Twin",Assumptions!$A$8:$A$46,0)))*((K$10+K$11)*INDEX(Assumptions!$E$60:$E$65,MATCH('Cash flow forecast'!$B12,Assumptions!$A$60:$A$65,0)))))*(1+Assumptions!$B$67) -> 3699.675 | ... Z12: =(((INDEX(Assumptions!$B$8:$B$46,MATCH("Total Twin",Assumptions!$A$8:$A$46,0)))*((Z$10+Z$11)*INDEX(Assumptions!$E$60:$E$65,MATCH('Cash flow forecast'!$B12,Assumptions!$A$60:$A$65,0)))))*(1+Assumptions!$B$67) -> 0 | AA12: =SUMIFS($C12:$N12,$C$6:$N$6,AA$5) -> 10276.875 | AB12: =SUMIFS($C12:$N12,$C$6:$N$6,AB$5) -> 3699.675 | AC12: =SUMIFS($C12:$N12,$C$6:$N$6,AC$5) -> 9249.1875 | AD12: =SUMIFS($C12:$N12,$C$6:$N$6,AD$5) -> 3699.675 | AE12: =SUM($C12:$N12) -> 26925.412 | AF12: =SUMIFS($O12:$Z12,$O$6:$Z$6,AF$5) -> 9249.1875 | AG12: =SUMIFS($O12:$Z12,$O$6:$Z$6,AG$5) -> 3699.675 | AH12: =SUMIFS($O12:$Z12,$O$6:$Z$6,AH$5) -> 9249.1875 | AI12: =SUMIFS($O12:$Z12,$O$6:$Z$6,AI$5) -> 12948.862 | AJ12: =SUM($O12:$Z12) -> 35146.912 | AK12: =AVERAGE(AE12,AJ12)/AVERAGE($AE$58,$AJ$58) -> 0.044935212
B13: Full Package Orders | C13: =((INDEX(Assumptions!$B$8:$B$46,MATCH("Total Full",Assumptions!$A$8:$A$46,0)))*((C$10+C$11)*INDEX(Assumptions!$E$60:$E$65,MATCH('Cash flow forecast'!$B13,Assumptions!$A$60:$A$65,0)))) -> 0 | D13: =(((INDEX(Assumptions!$B$8:$B$46,MATCH("Total Full",Assumptions!$A$8:$A$46,0)))*((D$10+D$11)*INDEX(Assumptions!$E$60:$E$65,MATCH('Cash flow forecast'!$B13,Assumptions!$A$60:$A$65,0)))))*(1+Assumptions!$B$67) -> 0 | E13: =(((INDEX(Assumptions!$B$8:$B$46,MATCH("Total Full",Assumptions!$A$8:$A$46,0)))*((E$10+E$11)*INDEX(Assumptions!$E$60:$E$65,MATCH('Cash flow forecast'!$B13,Assumptions!$A$60:$A$65,0)))))*(1+Assumptions!$B$67) -> 0 | F13: =(((INDEX(Assumptions!$B$8:$B$46,MATCH("Total Full",Assumptions!$A$8:$A$46,0)))*((F$10+F$11)*INDEX(Assumptions!$E$60:$E$65,MATCH('Cash flow forecast'!$B13,Assumptions!$A$60:$A$65,0)))))*(1+Assumptions!$B$67) -> 0 | G13: =(((INDEX(Assumptions!$B$8:$B$46,MATCH("Total Full",Assumptions!$A$8:$A$46,0)))*((G$10+G$11)*INDEX(Assumptions!$E$60:$E$65,MATCH('Cash flow forecast'!$B13,Assumptions!$A$60:$A$65,0)))))*(1+Assumptions!$B$67) -> 0 | H13: =(((INDEX(Assumptions!$B$8:$B$46,MATCH("Total Full",Assumptions!$A$8:$A$46,0)))*((H$10+H$11)*INDEX(Assumptions!$E$60:$E$65,MATCH('Cash flow forecast'!$B13,Assumptions!$A$60:$A$65,0)))))*(1+Assumptions!$B$67) -> 0 | I13: =(((INDEX(Assumptions!$B$8:$B$46,MATCH("Total Full",Assumptions!$A$8:$A$46,0)))*((I$10+I$11)*INDEX(Assumptions!$E$60:$E$65,MATCH('Cash flow forecast'!$B13,Assumptions!$A$60:$A$65,0)))))*(1+Assumptions!$B$67) -> 0 | J13: =(((INDEX(Assumptions!$B$8:$B$46,MATCH("Total Full",Assumptions!$A$8:$A$46,0)))*((J$10+J$11)*INDEX(Assumptions!$E$60:$E$65,MATCH('Cash flow forecast'!$B13,Assumptions!$A$60:$A$65,0)))))*(1+Assumptions!$B$67) -> 0 | K13: =(((INDEX(Assumptions!$B$8:$B$46,MATCH("Total Full",Assumptions!$A$8:$A$46,0)))*((K$10+K$11)*INDEX(Assumptions!$E$60:$E$65,MATCH('Cash flow forecast'!$B13,Assumptions!$A$60:$A$65,0)))))*(1+Assumptions!$B$67) -> 0 | ... Z13: =(((INDEX(Assumptions!$B$8:$B$46,MATCH("Total Full",Assumptions!$A$8:$A$46,0)))*((Z$10+Z$11)*INDEX(Assumptions!$E$60:$E$65,MATCH('Cash flow forecast'!$B13,Assumptions!$A$60:$A$65,0)))))*(1+Assumptions!$B$67) -> 0 | AA13: =SUMIFS($C13:$N13,$C$6:$N$6,AA$5) -> 0 | AB13: =SUMIFS($C13:$N13,$C$6:$N$6,AB$5) -> 0 | AC13: =SUMIFS($C13:$N13,$C$6:$N$6,AC$5) -> 0 | AD13: =SUMIFS($C13:$N13,$C$6:$N$6,AD$5) -> 0 | AE13: =SUM($C13:$N13) -> 0 | AF13: =SUMIFS($O13:$Z13,$O$6:$Z$6,AF$5) -> 0 | AG13: =SUMIFS($O13:$Z13,$O$6:$Z$6,AG$5) -> 0 | AH13: =SUMIFS($O13:$Z13,$O$6:$Z$6,AH$5) -> 0 | AI13: =SUMIFS($O13:$Z13,$O$6:$Z$6,AI$5) -> 0 | AJ13: =SUM($O13:$Z13) -> 0 | AK13: =AVERAGE(AE13,AJ13)/AVERAGE($AE$58,$AJ$58) -> 0
B14: Queen Package Orders | C14: =((INDEX(Assumptions!$B$8:$B$46,MATCH("Total Queen",Assumptions!$A$8:$A$46,0)))*((C$10+C$11)*INDEX(Assumptions!$E$60:$E$65,MATCH('Cash flow forecast'!$B14,Assumptions!$A$60:$A$65,0)))) -> 117000 | D14: =(((INDEX(Assumptions!$B$8:$B$46,MATCH("Total Queen",Assumptions!$A$8:$A$46,0)))*((D$10+D$11)*INDEX(Assumptions!$E$60:$E$65,MATCH('Cash flow forecast'!$B14,Assumptions!$A$60:$A$65,0)))))*(1+Assumptions!$B$67) -> 0 | E14: =(((INDEX(Assumptions!$B$8:$B$46,MATCH("Total Queen",Assumptions!$A$8:$A$46,0)))*((E$10+E$11)*INDEX(Assumptions!$E$60:$E$65,MATCH('Cash flow forecast'!$B14,Assumptions!$A$60:$A$65,0)))))*(1+Assumptions!$B$67) -> 42120 | F14: =(((INDEX(Assumptions!$B$8:$B$46,MATCH("Total Queen",Assumptions!$A$8:$A$46,0)))*((F$10+F$11)*INDEX(Assumptions!$E$60:$E$65,MATCH('Cash flow forecast'!$B14,Assumptions!$A$60:$A$65,0)))))*(1+Assumptions!$B$67) -> 0 | G14: =(((INDEX(Assumptions!$B$8:$B$46,MATCH("Total Queen",Assumptions!$A$8:$A$46,0)))*((G$10+G$11)*INDEX(Assumptions!$E$60:$E$65,MATCH('Cash flow forecast'!$B14,Assumptions!$A$60:$A$65,0)))))*(1+Assumptions!$B$67) -> 0 | H14: =(((INDEX(Assumptions!$B$8:$B$46,MATCH("Total Queen",Assumptions!$A$8:$A$46,0)))*((H$10+H$11)*INDEX(Assumptions!$E$60:$E$65,MATCH('Cash flow forecast'!$B14,Assumptions!$A$60:$A$65,0)))))*(1+Assumptions!$B$67) -> 0 | I14: =(((INDEX(Assumptions!$B$8:$B$46,MATCH("Total Queen",Assumptions!$A$8:$A$46,0)))*((I$10+I$11)*INDEX(Assumptions!$E$60:$E$65,MATCH('Cash flow forecast'!$B14,Assumptions!$A$60:$A$65,0)))))*(1+Assumptions!$B$67) -> 105300 | J14: =(((INDEX(Assumptions!$B$8:$B$46,MATCH("Total Queen",Assumptions!$A$8:$A$46,0)))*((J$10+J$11)*INDEX(Assumptions!$E$60:$E$65,MATCH('Cash flow forecast'!$B14,Assumptions!$A$60:$A$65,0)))))*(1+Assumptions!$B$67) -> 0 | K14: =(((INDEX(Assumptions!$B$8:$B$46,MATCH("Total Queen",Assumptions!$A$8:$A$46,0)))*((K$10+K$11)*INDEX(Assumptions!$E$60:$E$65,MATCH('Cash flow forecast'!$B14,Assumptions!$A$60:$A$65,0)))))*(1+Assumptions!$B$67) -> 42120 | ... Z14: =(((INDEX(Assumptions!$B$8:$B$46,MATCH("Total Queen",Assumptions!$A$8:$A$46,0)))*((Z$10+Z$11)*INDEX(Assumptions!$E$60:$E$65,MATCH('Cash flow forecast'!$B14,Assumptions!$A$60:$A$65,0)))))*(1+Assumptions!$B$67) -> 0 | AA14: =SUMIFS($C14:$N14,$C$6:$N$6,AA$5) -> 117000 | AB14: =SUMIFS($C14:$N14,$C$6:$N$6,AB$5) -> 42120 | AC14: =SUMIFS($C14:$N14,$C$6:$N$6,AC$5) -> 105300 | AD14: =SUMIFS($C14:$N14,$C$6:$N$6,AD$5) -> 42120 | AE14: =SUM($C14:$N14) -> 306540 | AF14: =SUMIFS($O14:$Z14,$O$6:$Z$6,AF$5) -> 105300 | AG14: =SUMIFS($O14:$Z14,$O$6:$Z$6,AG$5) -> 42120 | AH14: =SUMIFS($O14:$Z14,$O$6:$Z$6,AH$5) -> 105300 | AI14: =SUMIFS($O14:$Z14,$O$6:$Z$6,AI$5) -> 147420 | AJ14: =SUM($O14:$Z14) -> 400140 | AK14: =AVERAGE(AE14,AJ14)/AVERAGE($AE$58,$AJ$58) -> 0.51157767
B15: King Package Orders | C15: =((INDEX(Assumptions!$B$8:$B$46,MATCH("Total King",Assumptions!$A$8:$A$46,0)))*((C$10+C$11)*INDEX(Assumptions!$E$60:$E$65,MATCH('Cash flow forecast'!$B15,Assumptions!$A$60:$A$65,0)))) -> 19125 | D15: =(((INDEX(Assumptions!$B$8:$B$46,MATCH("Total King",Assumptions!$A$8:$A$46,0)))*((D$10+D$11)*INDEX(Assumptions!$E$60:$E$65,MATCH('Cash flow forecast'!$B15,Assumptions!$A$60:$A$65,0)))))*(1+Assumptions!$B$67) -> 0 | E15: =(((INDEX(Assumptions!$B$8:$B$46,MATCH("Total King",Assumptions!$A$8:$A$46,0)))*((E$10+E$11)*INDEX(Assumptions!$E$60:$E$65,MATCH('Cash flow forecast'!$B15,Assumptions!$A$60:$A$65,0)))))*(1+Assumptions!$B$67) -> 6885 | F15: =(((INDEX(Assumptions!$B$8:$B$46,MATCH("Total King",Assumptions!$A$8:$A$46,0)))*((F$10+F$11)*INDEX(Assumptions!$E$60:$E$65,MATCH('Cash flow forecast'!$B15,Assumptions!$A$60:$A$65,0)))))*(1+Assumptions!$B$67) -> 0 | G15: =(((INDEX(Assumptions!$B$8:$B$46,MATCH("Total King",Assumptions!$A$8:$A$46,0)))*((G$10+G$11)*INDEX(Assumptions!$E$60:$E$65,MATCH('Cash flow forecast'!$B15,Assumptions!$A$60:$A$65,0)))))*(1+Assumptions!$B$67) -> 0 | H15: =(((INDEX(Assumptions!$B$8:$B$46,MATCH("Total King",Assumptions!$A$8:$A$46,0)))*((H$10+H$11)*INDEX(Assumptions!$E$60:$E$65,MATCH('Cash flow forecast'!$B15,Assumptions!$A$60:$A$65,0)))))*(1+Assumptions!$B$67) -> 0 | I15: =(((INDEX(Assumptions!$B$8:$B$46,MATCH("Total King",Assumptions!$A$8:$A$46,0)))*((I$10+I$11)*INDEX(Assumptions!$E$60:$E$65,MATCH('Cash flow forecast'!$B15,Assumptions!$A$60:$A$65,0)))))*(1+Assumptions!$B$67) -> 17212.5 | J15: =(((INDEX(Assumptions!$B$8:$B$46,MATCH("Total King",Assumptions!$A$8:$A$46,0)))*((J$10+J$11)*INDEX(Assumptions!$E$60:$E$65,MATCH('Cash flow forecast'!$B15,Assumptions!$A$60:$A$65,0)))))*(1+Assumptions!$B$67) -> 0 | K15: =(((INDEX(Assumptions!$B$8:$B$46,MATCH("Total King",Assumptions!$A$8:$A$46,0)))*((K$10+K$11)*INDEX(Assumptions!$E$60:$E$65,MATCH('Cash flow forecast'!$B15,Assumptions!$A$60:$A$65,0)))))*(1+Assumptions!$B$67) -> 6885 | ... Z15: =(((INDEX(Assumptions!$B$8:$B$46,MATCH("Total King",Assumptions!$A$8:$A$46,0)))*((Z$10+Z$11)*INDEX(Assumptions!$E$60:$E$65,MATCH('Cash flow forecast'!$B15,Assumptions!$A$60:$A$65,0)))))*(1+Assumptions!$B$67) -> 0 | AA15: =SUMIFS($C15:$N15,$C$6:$N$6,AA$5) -> 19125 | AB15: =SUMIFS($C15:$N15,$C$6:$N$6,AB$5) -> 6885 | AC15: =SUMIFS($C15:$N15,$C$6:$N$6,AC$5) -> 17212.5 | AD15: =SUMIFS($C15:$N15,$C$6:$N$6,AD$5) -> 6885 | AE15: =SUM($C15:$N15) -> 50107.5 | AF15: =SUMIFS($O15:$Z15,$O$6:$Z$6,AF$5) -> 17212.5 | AG15: =SUMIFS($O15:$Z15,$O$6:$Z$6,AG$5) -> 6885 | AH15: =SUMIFS($O15:$Z15,$O$6:$Z$6,AH$5) -> 17212.5 | AI15: =SUMIFS($O15:$Z15,$O$6:$Z$6,AI$5) -> 24097.5 | AJ15: =SUM($O15:$Z15) -> 65407.5 | AK15: =AVERAGE(AE15,AJ15)/AVERAGE($AE$58,$AJ$58) -> 0.083623273
B16: Universal Package Orders | C16: =((INDEX(Assumptions!$B$8:$B$46,MATCH("Total Universal",Assumptions!$A$8:$A$46,0)))*((C$10+C$11)*INDEX(Assumptions!$E$60:$E$65,MATCH('Cash flow forecast'!$B16,Assumptions!$A$60:$A$65,0)))) -> 0 | D16: =(((INDEX(Assumptions!$B$8:$B$46,MATCH("Total Universal",Assumptions!$A$8:$A$46,0)))*((D$10+D$11)*INDEX(Assumptions!$E$60:$E$65,MATCH('Cash flow forecast'!$B16,Assumptions!$A$60:$A$65,0)))))*(1+Assumptions!$B$67) -> 0 | E16: =(((INDEX(Assumptions!$B$8:$B$46,MATCH("Total Universal",Assumptions!$A$8:$A$46,0)))*((E$10+E$11)*INDEX(Assumptions!$E$60:$E$65,MATCH('Cash flow forecast'!$B16,Assumptions!$A$60:$A$65,0)))))*(1+Assumptions!$B$67) -> 0 | F16: =(((INDEX(Assumptions!$B$8:$B$46,MATCH("Total Universal",Assumptions!$A$8:$A$46,0)))*((F$10+F$11)*INDEX(Assumptions!$E$60:$E$65,MATCH('Cash flow forecast'!$B16,Assumptions!$A$60:$A$65,0)))))*(1+Assumptions!$B$67) -> 0 | G16: =(((INDEX(Assumptions!$B$8:$B$46,MATCH("Total Universal",Assumptions!$A$8:$A$46,0)))*((G$10+G$11)*INDEX(Assumptions!$E$60:$E$65,MATCH('Cash flow forecast'!$B16,Assumptions!$A$60:$A$65,0)))))*(1+Assumptions!$B$67) -> 0 | H16: =(((INDEX(Assumptions!$B$8:$B$46,MATCH("Total Universal",Assumptions!$A$8:$A$46,0)))*((H$10+H$11)*INDEX(Assumptions!$E$60:$E$65,MATCH('Cash flow forecast'!$B16,Assumptions!$A$60:$A$65,0)))))*(1+Assumptions!$B$67) -> 0 | I16: =(((INDEX(Assumptions!$B$8:$B$46,MATCH("Total Universal",Assumptions!$A$8:$A$46,0)))*((I$10+I$11)*INDEX(Assumptions!$E$60:$E$65,MATCH('Cash flow forecast'!$B16,Assumptions!$A$60:$A$65,0)))))*(1+Assumptions!$B$67) -> 0 | J16: =(((INDEX(Assumptions!$B$8:$B$46,MATCH("Total Universal",Assumptions!$A$8:$A$46,0)))*((J$10+J$11)*INDEX(Assumptions!$E$60:$E$65,MATCH('Cash flow forecast'!$B16,Assumptions!$A$60:$A$65,0)))))*(1+Assumptions!$B$67) -> 0 | K16: =(((INDEX(Assumptions!$B$8:$B$46,MATCH("Total Universal",Assumptions!$A$8:$A$46,0)))*((K$10+K$11)*INDEX(Assumptions!$E$60:$E$65,MATCH('Cash flow forecast'!$B16,Assumptions!$A$60:$A$65,0)))))*(1+Assumptions!$B$67) -> 0 | ... Z16: =(((INDEX(Assumptions!$B$8:$B$46,MATCH("Total Universal",Assumptions!$A$8:$A$46,0)))*((Z$10+Z$11)*INDEX(Assumptions!$E$60:$E$65,MATCH('Cash flow forecast'!$B16,Assumptions!$A$60:$A$65,0)))))*(1+Assumptions!$B$67) -> 0 | AA16: =SUMIFS($C16:$N16,$C$6:$N$6,AA$5) -> 0 | AB16: =SUMIFS($C16:$N16,$C$6:$N$6,AB$5) -> 0 | AC16: =SUMIFS($C16:$N16,$C$6:$N$6,AC$5) -> 0 | AD16: =SUMIFS($C16:$N16,$C$6:$N$6,AD$5) -> 0 | AE16: =SUM($C16:$N16) -> 0 | AF16: =SUMIFS($O16:$Z16,$O$6:$Z$6,AF$5) -> 0 | AG16: =SUMIFS($O16:$Z16,$O$6:$Z$6,AG$5) -> 0 | AH16: =SUMIFS($O16:$Z16,$O$6:$Z$6,AH$5) -> 0 | AI16: =SUMIFS($O16:$Z16,$O$6:$Z$6,AI$5) -> 0 | AJ16: =SUM($O16:$Z16) -> 0 | AK16: =AVERAGE(AE16,AJ16)/AVERAGE($AE$58,$AJ$58) -> 0
B17: Total | C17: =SUM(C12:C16) -> 146401.88 | D17: =SUM(D12:D16) -> 0 | E17: =SUM(E12:E16) -> 52704.675 | F17: =SUM(F12:F16) -> 0 | G17: =SUM(G12:G16) -> 0 | H17: =SUM(H12:H16) -> 0 | I17: =SUM(I12:I16) -> 131761.69 | J17: =SUM(J12:J16) -> 0 | ... AJ17: =SUM(AJ12:AJ16) -> 500694.41 | AK17: =AVERAGE(AE17,AJ17)/AVERAGE($AE$58,$AJ$58) -> 0.64013616
B18: Medium Hotels
B19: # of New Hotels | C19: =SUMIFS(Formatting!$A$33:$A$37,Formatting!$E$33:$E$37,'Cash flow forecast'!C$5) -> 1 | D19: =SUMIFS(Formatting!$A$33:$A$37,Formatting!$E$33:$E$37,'Cash flow forecast'!D$5) -> 0 | E19: =SUMIFS(Formatting!$A$33:$A$37,Formatting!$E$33:$E$37,'Cash flow forecast'!E$5) -> 1 | F19: =SUMIFS(Formatting!$A$33:$A$37,Formatting!$E$33:$E$37,'Cash flow forecast'!F$5) -> 0 | G19: =SUMIFS(Formatting!$A$33:$A$37,Formatting!$E$33:$E$37,'Cash flow forecast'!G$5) -> 0 | H19: =SUMIFS(Formatting!$A$33:$A$37,Formatting!$E$33:$E$37,'Cash flow forecast'!H$5) -> 0 | I19: =SUMIFS(Formatting!$A$33:$A$37,Formatting!$E$33:$E$37,'Cash flow forecast'!I$5) -> 0 | J19: =SUMIFS(Formatting!$A$33:$A$37,Formatting!$E$33:$E$37,'Cash flow forecast'!J$5) -> 0 | ... Z19: =SUMIFS(Formatting!$A$33:$A$37,Formatting!$E$33:$E$37,'Cash flow forecast'!Z$5) -> 0
B20: # of Renew Orders | C20: =IFERROR(INDEX(Formatting!$F$34:$T$34,MATCH('Cash flow forecast'!C$5,Formatting!$F$33:$T$33,0)),0)+IFERROR(INDEX(Formatting!$F$36:$T$36,MATCH('Cash flow forecast'!C$5,Formatting!$F$35:$T$35,0)),0)+IFERROR(INDEX(Formatting!$F$38:$T$38,MATCH('Cash flow forecast'!C$5,Formatting!$F$37:$T$37,0)),0) -> 0 | D20: =IFERROR(INDEX(Formatting!$F$34:$T$34,MATCH('Cash flow forecast'!D$5,Formatting!$F$33:$T$33,0)),0)+IFERROR(INDEX(Formatting!$F$36:$T$36,MATCH('Cash flow forecast'!D$5,Formatting!$F$35:$T$35,0)),0)+IFERROR(INDEX(Formatting!$F$38:$T$38,MATCH('Cash flow forecast'!D$5,Formatting!$F$37:$T$37,0)),0) -> 0 | E20: =IFERROR(INDEX(Formatting!$F$34:$T$34,MATCH('Cash flow forecast'!E$5,Formatting!$F$33:$T$33,0)),0)+IFERROR(INDEX(Formatting!$F$36:$T$36,MATCH('Cash flow forecast'!E$5,Formatting!$F$35:$T$35,0)),0)+IFERROR(INDEX(Formatting!$F$38:$T$38,MATCH('Cash flow forecast'!E$5,Formatting!$F$37:$T$37,0)),0) -> 0 | F20: =IFERROR(INDEX(Formatting!$F$34:$T$34,MATCH('Cash flow forecast'!F$5,Formatting!$F$33:$T$33,0)),0)+IFERROR(INDEX(Formatting!$F$36:$T$36,MATCH('Cash flow forecast'!F$5,Formatting!$F$35:$T$35,0)),0)+IFERROR(INDEX(Formatting!$F$38:$T$38,MATCH('Cash flow forecast'!F$5,Formatting!$F$37:$T$37,0)),0) -> 0 | G20: =IFERROR(INDEX(Formatting!$F$34:$T$34,MATCH('Cash flow forecast'!G$5,Formatting!$F$33:$T$33,0)),0)+IFERROR(INDEX(Formatting!$F$36:$T$36,MATCH('Cash flow forecast'!G$5,Formatting!$F$35:$T$35,0)),0)+IFERROR(INDEX(Formatting!$F$38:$T$38,MATCH('Cash flow forecast'!G$5,Formatting!$F$37:$T$37,0)),0) -> 0 | H20: =IFERROR(INDEX(Formatting!$F$34:$T$34,MATCH('Cash flow forecast'!H$5,Formatting!$F$33:$T$33,0)),0)+IFERROR(INDEX(Formatting!$F$36:$T$36,MATCH('Cash flow forecast'!H$5,Formatting!$F$35:$T$35,0)),0)+IFERROR(INDEX(Formatting!$F$38:$T$38,MATCH('Cash flow forecast'!H$5,Formatting!$F$37:$T$37,0)),0) -> 0 | I20: =IFERROR(INDEX(Formatting!$F$34:$T$34,MATCH('Cash flow forecast'!I$5,Formatting!$F$33:$T$33,0)),0)+IFERROR(INDEX(Formatting!$F$36:$T$36,MATCH('Cash flow forecast'!I$5,Formatting!$F$35:$T$35,0)),0)+IFERROR(INDEX(Formatting!$F$38:$T$38,MATCH('Cash flow forecast'!I$5,Formatting!$F$37:$T$37,0)),0) -> 1 | J20: =IFERROR(INDEX(Formatting!$F$34:$T$34,MATCH('Cash flow forecast'!J$5,Formatting!$F$33:$T$33,0)),0)+IFERROR(INDEX(Formatting!$F$36:$T$36,MATCH('Cash flow forecast'!J$5,Formatting!$F$35:$T$35,0)),0)+IFERROR(INDEX(Formatting!$F$38:$T$38,MATCH('Cash flow forecast'!J$5,Formatting!$F$37:$T$37,0)),0) -> 0 | ... Z20: =IFERROR(INDEX(Formatting!$F$34:$T$34,MATCH('Cash flow forecast'!Z$5,Formatting!$F$33:$T$33,0)),0)+IFERROR(INDEX(Formatting!$F$36:$T$36,MATCH('Cash flow forecast'!Z$5,Formatting!$F$35:$T$35,0)),0)+IFERROR(INDEX(Formatting!$F$38:$T$38,MATCH('Cash flow forecast'!Z$5,Formatting!$F$37:$T$37,0)),0) -> 0
B21: Twin Package Orders | C21: =((INDEX(Assumptions!$B$8:$B$46,MATCH("Total Twin",Assumptions!$A$8:$A$46,0)))*((C$19+C$20)*INDEX(Assumptions!$E$78:$E$83,MATCH('Cash flow forecast'!$B21,Assumptions!$A$78:$A$83,0)))) -> 2055.375 | D21: =(((INDEX(Assumptions!$B$8:$B$46,MATCH("Total Twin",Assumptions!$A$8:$A$46,0)))*((D$19+D$20)*INDEX(Assumptions!$E$78:$E$83,MATCH('Cash flow forecast'!$B21,Assumptions!$A$78:$A$83,0)))))*(1+Assumptions!$B$85) -> 0 | E21: =(((INDEX(Assumptions!$B$8:$B$46,MATCH("Total Twin",Assumptions!$A$8:$A$46,0)))*((E$19+E$20)*INDEX(Assumptions!$E$78:$E$83,MATCH('Cash flow forecast'!$B21,Assumptions!$A$78:$A$83,0)))))*(1+Assumptions!$B$85) -> 1849.8375 | F21: =(((INDEX(Assumptions!$B$8:$B$46,MATCH("Total Twin",Assumptions!$A$8:$A$46,0)))*((F$19+F$20)*INDEX(Assumptions!$E$78:$E$83,MATCH('Cash flow forecast'!$B21,Assumptions!$A$78:$A$83,0)))))*(1+Assumptions!$B$85) -> 0 | G21: =(((INDEX(Assumptions!$B$8:$B$46,MATCH("Total Twin",Assumptions!$A$8:$A$46,0)))*((G$19+G$20)*INDEX(Assumptions!$E$78:$E$83,MATCH('Cash flow forecast'!$B21,Assumptions!$A$78:$A$83,0)))))*(1+Assumptions!$B$85) -> 0 | H21: =(((INDEX(Assumptions!$B$8:$B$46,MATCH("Total Twin",Assumptions!$A$8:$A$46,0)))*((H$19+H$20)*INDEX(Assumptions!$E$78:$E$83,MATCH('Cash flow forecast'!$B21,Assumptions!$A$78:$A$83,0)))))*(1+Assumptions!$B$85) -> 0 | I21: =(((INDEX(Assumptions!$B$8:$B$46,MATCH("Total Twin",Assumptions!$A$8:$A$46,0)))*((I$19+I$20)*INDEX(Assumptions!$E$78:$E$83,MATCH('Cash flow forecast'!$B21,Assumptions!$A$78:$A$83,0)))))*(1+Assumptions!$B$85) -> 1849.8375 | J21: =(((INDEX(Assumptions!$B$8:$B$46,MATCH("Total Twin",Assumptions!$A$8:$A$46,0)))*((J$19+J$20)*INDEX(Assumptions!$E$78:$E$83,MATCH('Cash flow forecast'!$B21,Assumptions!$A$78:$A$83,0)))))*(1+Assumptions!$B$85) -> 0 | K21: =(((INDEX(Assumptions!$B$8:$B$46,MATCH("Total Twin",Assumptions!$A$8:$A$46,0)))*((K$19+K$20)*INDEX(Assumptions!$E$78:$E$83,MATCH('Cash flow forecast'!$B21,Assumptions!$A$78:$A$83,0)))))*(1+Assumptions!$B$85) -> 1849.8375 | ... Z21: =(((INDEX(Assumptions!$B$8:$B$46,MATCH("Total Twin",Assumptions!$A$8:$A$46,0)))*((Z$19+Z$20)*INDEX(Assumptions!$E$78:$E$83,MATCH('Cash flow forecast'!$B21,Assumptions!$A$78:$A$83,0)))))*(1+Assumptions!$B$85) -> 0 | AA21: =SUMIFS($C21:$N21,$C$6:$N$6,AA$5) -> 2055.375 | AB21: =SUMIFS($C21:$N21,$C$6:$N$6,AB$5) -> 1849.8375 | AC21: =SUMIFS($C21:$N21,$C$6:$N$6,AC$5) -> 1849.8375 | AD21: =SUMIFS($C21:$N21,$C$6:$N$6,AD$5) -> 1849.8375 | AE21: =SUM($C21:$N21) -> 7604.8875 | AF21: =SUMIFS($O21:$Z21,$O$6:$Z$6,AF$5) -> 1849.8375 | AG21: =SUMIFS($O21:$Z21,$O$6:$Z$6,AG$5) -> 1849.8375 | AH21: =SUMIFS($O21:$Z21,$O$6:$Z$6,AH$5) -> 1849.8375 | AI21: =SUMIFS($O21:$Z21,$O$6:$Z$6,AI$5) -> 1849.8375 | AJ21: =SUM($O21:$Z21) -> 7399.35 | AK21: =AVERAGE(AE21,AJ21)/AVERAGE($AE$58,$AJ$58) -> 0.010861823
B22: Full Package Orders | C22: =((INDEX(Assumptions!$B$8:$B$46,MATCH("Total Full",Assumptions!$A$8:$A$46,0)))*((C$19+C$20)*INDEX(Assumptions!$E$78:$E$83,MATCH('Cash flow forecast'!$B22,Assumptions!$A$78:$A$83,0)))) -> 0 | D22: =(((INDEX(Assumptions!$B$8:$B$46,MATCH("Total Full",Assumptions!$A$8:$A$46,0)))*((D$19+D$20)*INDEX(Assumptions!$E$78:$E$83,MATCH('Cash flow forecast'!$B22,Assumptions!$A$78:$A$83,0)))))*(1+Assumptions!$B$85) -> 0 | E22: =(((INDEX(Assumptions!$B$8:$B$46,MATCH("Total Full",Assumptions!$A$8:$A$46,0)))*((E$19+E$20)*INDEX(Assumptions!$E$78:$E$83,MATCH('Cash flow forecast'!$B22,Assumptions!$A$78:$A$83,0)))))*(1+Assumptions!$B$85) -> 0 | F22: =(((INDEX(Assumptions!$B$8:$B$46,MATCH("Total Full",Assumptions!$A$8:$A$46,0)))*((F$19+F$20)*INDEX(Assumptions!$E$78:$E$83,MATCH('Cash flow forecast'!$B22,Assumptions!$A$78:$A$83,0)))))*(1+Assumptions!$B$85) -> 0 | G22: =(((INDEX(Assumptions!$B$8:$B$46,MATCH("Total Full",Assumptions!$A$8:$A$46,0)))*((G$19+G$20)*INDEX(Assumptions!$E$78:$E$83,MATCH('Cash flow forecast'!$B22,Assumptions!$A$78:$A$83,0)))))*(1+Assumptions!$B$85) -> 0 | H22: =(((INDEX(Assumptions!$B$8:$B$46,MATCH("Total Full",Assumptions!$A$8:$A$46,0)))*((H$19+H$20)*INDEX(Assumptions!$E$78:$E$83,MATCH('Cash flow forecast'!$B22,Assumptions!$A$78:$A$83,0)))))*(1+Assumptions!$B$85) -> 0 | I22: =(((INDEX(Assumptions!$B$8:$B$46,MATCH("Total Full",Assumptions!$A$8:$A$46,0)))*((I$19+I$20)*INDEX(Assumptions!$E$78:$E$83,MATCH('Cash flow forecast'!$B22,Assumptions!$A$78:$A$83,0)))))*(1+Assumptions!$B$85) -> 0 | J22: =(((INDEX(Assumptions!$B$8:$B$46,MATCH("Total Full",Assumptions!$A$8:$A$46,0)))*((J$19+J$20)*INDEX(Assumptions!$E$78:$E$83,MATCH('Cash flow forecast'!$B22,Assumptions!$A$78:$A$83,0)))))*(1+Assumptions!$B$85) -> 0 | K22: =(((INDEX(Assumptions!$B$8:$B$46,MATCH("Total Full",Assumptions!$A$8:$A$46,0)))*((K$19+K$20)*INDEX(Assumptions!$E$78:$E$83,MATCH('Cash flow forecast'!$B22,Assumptions!$A$78:$A$83,0)))))*(1+Assumptions!$B$85) -> 0 | ... Z22: =(((INDEX(Assumptions!$B$8:$B$46,MATCH("Total Full",Assumptions!$A$8:$A$46,0)))*((Z$19+Z$20)*INDEX(Assumptions!$E$78:$E$83,MATCH('Cash flow forecast'!$B22,Assumptions!$A$78:$A$83,0)))))*(1+Assumptions!$B$85) -> 0 | AA22: =SUMIFS($C22:$N22,$C$6:$N$6,AA$5) -> 0 | AB22: =SUMIFS($C22:$N22,$C$6:$N$6,AB$5) -> 0 | AC22: =SUMIFS($C22:$N22,$C$6:$N$6,AC$5) -> 0 | AD22: =SUMIFS($C22:$N22,$C$6:$N$6,AD$5) -> 0 | AE22: =SUM($C22:$N22) -> 0 | AF22: =SUMIFS($O22:$Z22,$O$6:$Z$6,AF$5) -> 0 | AG22: =SUMIFS($O22:$Z22,$O$6:$Z$6,AG$5) -> 0 | AH22: =SUMIFS($O22:$Z22,$O$6:$Z$6,AH$5) -> 0 | AI22: =SUMIFS($O22:$Z22,$O$6:$Z$6,AI$5) -> 0 | AJ22: =SUM($O22:$Z22) -> 0 | AK22: =AVERAGE(AE22,AJ22)/AVERAGE($AE$58,$AJ$58) -> 0
B23: Queen Package Orders | C23: =((INDEX(Assumptions!$B$8:$B$46,MATCH("Total Queen",Assumptions!$A$8:$A$46,0)))*((C$19+C$20)*INDEX(Assumptions!$E$78:$E$83,MATCH('Cash flow forecast'!$B23,Assumptions!$A$78:$A$83,0)))) -> 23400 | D23: =(((INDEX(Assumptions!$B$8:$B$46,MATCH("Total Queen",Assumptions!$A$8:$A$46,0)))*((D$19+D$20)*INDEX(Assumptions!$E$78:$E$83,MATCH('Cash flow forecast'!$B23,Assumptions!$A$78:$A$83,0)))))*(1+Assumptions!$B$85) -> 0 | E23: =(((INDEX(Assumptions!$B$8:$B$46,MATCH("Total Queen",Assumptions!$A$8:$A$46,0)))*((E$19+E$20)*INDEX(Assumptions!$E$78:$E$83,MATCH('Cash flow forecast'!$B23,Assumptions!$A$78:$A$83,0)))))*(1+Assumptions!$B$85) -> 21060 | F23: =(((INDEX(Assumptions!$B$8:$B$46,MATCH("Total Queen",Assumptions!$A$8:$A$46,0)))*((F$19+F$20)*INDEX(Assumptions!$E$78:$E$83,MATCH('Cash flow forecast'!$B23,Assumptions!$A$78:$A$83,0)))))*(1+Assumptions!$B$85) -> 0 | G23: =(((INDEX(Assumptions!$B$8:$B$46,MATCH("Total Queen",Assumptions!$A$8:$A$46,0)))*((G$19+G$20)*INDEX(Assumptions!$E$78:$E$83,MATCH('Cash flow forecast'!$B23,Assumptions!$A$78:$A$83,0)))))*(1+Assumptions!$B$85) -> 0 | H23: =(((INDEX(Assumptions!$B$8:$B$46,MATCH("Total Queen",Assumptions!$A$8:$A$46,0)))*((H$19+H$20)*INDEX(Assumptions!$E$78:$E$83,MATCH('Cash flow forecast'!$B23,Assumptions!$A$78:$A$83,0)))))*(1+Assumptions!$B$85) -> 0 | I23: =(((INDEX(Assumptions!$B$8:$B$46,MATCH("Total Queen",Assumptions!$A$8:$A$46,0)))*((I$19+I$20)*INDEX(Assumptions!$E$78:$E$83,MATCH('Cash flow forecast'!$B23,Assumptions!$A$78:$A$83,0)))))*(1+Assumptions!$B$85) -> 21060 | J23: =(((INDEX(Assumptions!$B$8:$B$46,MATCH("Total Queen",Assumptions!$A$8:$A$46,0)))*((J$19+J$20)*INDEX(Assumptions!$E$78:$E$83,MATCH('Cash flow forecast'!$B23,Assumptions!$A$78:$A$83,0)))))*(1+Assumptions!$B$85) -> 0 | K23: =(((INDEX(Assumptions!$B$8:$B$46,MATCH("Total Queen",Assumptions!$A$8:$A$46,0)))*((K$19+K$20)*INDEX(Assumptions!$E$78:$E$83,MATCH('Cash flow forecast'!$B23,Assumptions!$A$78:$A$83,0)))))*(1+Assumptions!$B$85) -> 21060 | ... Z23: =(((INDEX(Assumptions!$B$8:$B$46,MATCH("Total Queen",Assumptions!$A$8:$A$46,0)))*((Z$19+Z$20)*INDEX(Assumptions!$E$78:$E$83,MATCH('Cash flow forecast'!$B23,Assumptions!$A$78:$A$83,0)))))*(1+Assumptions!$B$85) -> 0 | AA23: =SUMIFS($C23:$N23,$C$6:$N$6,AA$5) -> 23400 | AB23: =SUMIFS($C23:$N23,$C$6:$N$6,AB$5) -> 21060 | AC23: =SUMIFS($C23:$N23,$C$6:$N$6,AC$5) -> 21060 | AD23: =SUMIFS($C23:$N23,$C$6:$N$6,AD$5) -> 21060 | AE23: =SUM($C23:$N23) -> 86580 | AF23: =SUMIFS($O23:$Z23,$O$6:$Z$6,AF$5) -> 21060 | AG23: =SUMIFS($O23:$Z23,$O$6:$Z$6,AG$5) -> 21060 | AH23: =SUMIFS($O23:$Z23,$O$6:$Z$6,AH$5) -> 21060 | AI23: =SUMIFS($O23:$Z23,$O$6:$Z$6,AI$5) -> 21060 | AJ23: =SUM($O23:$Z23) -> 84240 | AK23: =AVERAGE(AE23,AJ23)/AVERAGE($AE$58,$AJ$58) -> 0.1236595
B24: King Package Orders | C24: =((INDEX(Assumptions!$B$8:$B$46,MATCH("Total King",Assumptions!$A$8:$A$46,0)))*((C$19+C$20)*INDEX(Assumptions!$E$78:$E$83,MATCH('Cash flow forecast'!$B24,Assumptions!$A$78:$A$83,0)))) -> 3825 | D24: =(((INDEX(Assumptions!$B$8:$B$46,MATCH("Total King",Assumptions!$A$8:$A$46,0)))*((D$19+D$20)*INDEX(Assumptions!$E$78:$E$83,MATCH('Cash flow forecast'!$B24,Assumptions!$A$78:$A$83,0)))))*(1+Assumptions!$B$85) -> 0 | E24: =(((INDEX(Assumptions!$B$8:$B$46,MATCH("Total King",Assumptions!$A$8:$A$46,0)))*((E$19+E$20)*INDEX(Assumptions!$E$78:$E$83,MATCH('Cash flow forecast'!$B24,Assumptions!$A$78:$A$83,0)))))*(1+Assumptions!$B$85) -> 3442.5 | F24: =(((INDEX(Assumptions!$B$8:$B$46,MATCH("Total King",Assumptions!$A$8:$A$46,0)))*((F$19+F$20)*INDEX(Assumptions!$E$78:$E$83,MATCH('Cash flow forecast'!$B24,Assumptions!$A$78:$A$83,0)))))*(1+Assumptions!$B$85) -> 0 | G24: =(((INDEX(Assumptions!$B$8:$B$46,MATCH("Total King",Assumptions!$A$8:$A$46,0)))*((G$19+G$20)*INDEX(Assumptions!$E$78:$E$83,MATCH('Cash flow forecast'!$B24,Assumptions!$A$78:$A$83,0)))))*(1+Assumptions!$B$85) -> 0 | H24: =(((INDEX(Assumptions!$B$8:$B$46,MATCH("Total King",Assumptions!$A$8:$A$46,0)))*((H$19+H$20)*INDEX(Assumptions!$E$78:$E$83,MATCH('Cash flow forecast'!$B24,Assumptions!$A$78:$A$83,0)))))*(1+Assumptions!$B$85) -> 0 | I24: =(((INDEX(Assumptions!$B$8:$B$46,MATCH("Total King",Assumptions!$A$8:$A$46,0)))*((I$19+I$20)*INDEX(Assumptions!$E$78:$E$83,MATCH('Cash flow forecast'!$B24,Assumptions!$A$78:$A$83,0)))))*(1+Assumptions!$B$85) -> 3442.5 | J24: =(((INDEX(Assumptions!$B$8:$B$46,MATCH("Total King",Assumptions!$A$8:$A$46,0)))*((J$19+J$20)*INDEX(Assumptions!$E$78:$E$83,MATCH('Cash flow forecast'!$B24,Assumptions!$A$78:$A$83,0)))))*(1+Assumptions!$B$85) -> 0 | K24: =(((INDEX(Assumptions!$B$8:$B$46,MATCH("Total King",Assumptions!$A$8:$A$46,0)))*((K$19+K$20)*INDEX(Assumptions!$E$78:$E$83,MATCH('Cash flow forecast'!$B24,Assumptions!$A$78:$A$83,0)))))*(1+Assumptions!$B$85) -> 3442.5 | ... Z24: =(((INDEX(Assumptions!$B$8:$B$46,MATCH("Total King",Assumptions!$A$8:$A$46,0)))*((Z$19+Z$20)*INDEX(Assumptions!$E$78:$E$83,MATCH('Cash flow forecast'!$B24,Assumptions!$A$78:$A$83,0)))))*(1+Assumptions!$B$85) -> 0 | AA24: =SUMIFS($C24:$N24,$C$6:$N$6,AA$5) -> 3825 | AB24: =SUMIFS($C24:$N24,$C$6:$N$6,AB$5) -> 3442.5 | AC24: =SUMIFS($C24:$N24,$C$6:$N$6,AC$5) -> 3442.5 | AD24: =SUMIFS($C24:$N24,$C$6:$N$6,AD$5) -> 3442.5 | AE24: =SUM($C24:$N24) -> 14152.5 | AF24: =SUMIFS($O24:$Z24,$O$6:$Z$6,AF$5) -> 3442.5 | AG24: =SUMIFS($O24:$Z24,$O$6:$Z$6,AG$5) -> 3442.5 | AH24: =SUMIFS($O24:$Z24,$O$6:$Z$6,AH$5) -> 3442.5 | AI24: =SUMIFS($O24:$Z24,$O$6:$Z$6,AI$5) -> 3442.5 | AJ24: =SUM($O24:$Z24) -> 13770 | AK24: =AVERAGE(AE24,AJ24)/AVERAGE($AE$58,$AJ$58) -> 0.020213573
B25: Universal Package Orders | C25: =((INDEX(Assumptions!$B$8:$B$46,MATCH("Total Universal",Assumptions!$A$8:$A$46,0)))*((C$19+C$20)*INDEX(Assumptions!$E$78:$E$83,MATCH('Cash flow forecast'!$B25,Assumptions!$A$78:$A$83,0)))) -> 0 | D25: =(((INDEX(Assumptions!$B$8:$B$46,MATCH("Total Universal",Assumptions!$A$8:$A$46,0)))*((D$19+D$20)*INDEX(Assumptions!$E$78:$E$83,MATCH('Cash flow forecast'!$B25,Assumptions!$A$78:$A$83,0)))))*(1+Assumptions!$B$85) -> 0 | E25: =(((INDEX(Assumptions!$B$8:$B$46,MATCH("Total Universal",Assumptions!$A$8:$A$46,0)))*((E$19+E$20)*INDEX(Assumptions!$E$78:$E$83,MATCH('Cash flow forecast'!$B25,Assumptions!$A$78:$A$83,0)))))*(1+Assumptions!$B$85) -> 0 | F25: =(((INDEX(Assumptions!$B$8:$B$46,MATCH("Total Universal",Assumptions!$A$8:$A$46,0)))*((F$19+F$20)*INDEX(Assumptions!$E$78:$E$83,MATCH('Cash flow forecast'!$B25,Assumptions!$A$78:$A$83,0)))))*(1+Assumptions!$B$85) -> 0 | G25: =(((INDEX(Assumptions!$B$8:$B$46,MATCH("Total Universal",Assumptions!$A$8:$A$46,0)))*((G$19+G$20)*INDEX(Assumptions!$E$78:$E$83,MATCH('Cash flow forecast'!$B25,Assumptions!$A$78:$A$83,0)))))*(1+Assumptions!$B$85) -> 0 | H25: =(((INDEX(Assumptions!$B$8:$B$46,MATCH("Total Universal",Assumptions!$A$8:$A$46,0)))*((H$19+H$20)*INDEX(Assumptions!$E$78:$E$83,MATCH('Cash flow forecast'!$B25,Assumptions!$A$78:$A$83,0)))))*(1+Assumptions!$B$85) -> 0 | I25: =(((INDEX(Assumptions!$B$8:$B$46,MATCH("Total Universal",Assumptions!$A$8:$A$46,0)))*((I$19+I$20)*INDEX(Assumptions!$E$78:$E$83,MATCH('Cash flow forecast'!$B25,Assumptions!$A$78:$A$83,0)))))*(1+Assumptions!$B$85) -> 0 | J25: =(((INDEX(Assumptions!$B$8:$B$46,MATCH("Total Universal",Assumptions!$A$8:$A$46,0)))*((J$19+J$20)*INDEX(Assumptions!$E$78:$E$83,MATCH('Cash flow forecast'!$B25,Assumptions!$A$78:$A$83,0)))))*(1+Assumptions!$B$85) -> 0 | K25: =(((INDEX(Assumptions!$B$8:$B$46,MATCH("Total Universal",Assumptions!$A$8:$A$46,0)))*((K$19+K$20)*INDEX(Assumptions!$E$78:$E$83,MATCH('Cash flow forecast'!$B25,Assumptions!$A$78:$A$83,0)))))*(1+Assumptions!$B$85) -> 0 | ... Z25: =(((INDEX(Assumptions!$B$8:$B$46,MATCH("Total Universal",Assumptions!$A$8:$A$46,0)))*((Z$19+Z$20)*INDEX(Assumptions!$E$78:$E$83,MATCH('Cash flow forecast'!$B25,Assumptions!$A$78:$A$83,0)))))*(1+Assumptions!$B$85) -> 0 | AA25: =SUMIFS($C25:$N25,$C$6:$N$6,AA$5) -> 0 | AB25: =SUMIFS($C25:$N25,$C$6:$N$6,AB$5) -> 0 | AC25: =SUMIFS($C25:$N25,$C$6:$N$6,AC$5) -> 0 | AD25: =SUMIFS($C25:$N25,$C$6:$N$6,AD$5) -> 0 | AE25: =SUM($C25:$N25) -> 0 | AF25: =SUMIFS($O25:$Z25,$O$6:$Z$6,AF$5) -> 0 | AG25: =SUMIFS($O25:$Z25,$O$6:$Z$6,AG$5) -> 0 | AH25: =SUMIFS($O25:$Z25,$O$6:$Z$6,AH$5) -> 0 | AI25: =SUMIFS($O25:$Z25,$O$6:$Z$6,AI$5) -> 0 | AJ25: =SUM($O25:$Z25) -> 0 | AK25: =AVERAGE(AE25,AJ25)/AVERAGE($AE$58,$AJ$58) -> 0
B26: Total | C26: =SUM(C21:C25) -> 29280.375 | D26: =SUM(D21:D25) -> 0 | E26: =SUM(E21:E25) -> 26352.338 | F26: =SUM(F21:F25) -> 0 | G26: =SUM(G21:G25) -> 0 | H26: =SUM(H21:H25) -> 0 | I26: =SUM(I21:I25) -> 26352.338 | J26: =SUM(J21:J25) -> 0 | ... AD26: =SUM(AD21:AD25) -> 26352.338 | AE26: =SUM($C26:$N26) -> 108337.39 | AF26: =SUM(AF21:AF25) -> 26352.338 | AG26: =SUM(AG21:AG25) -> 26352.338 | AH26: =SUM(AH21:AH25) -> 26352.338 | AI26: =SUM(AI21:AI25) -> 26352.338 | AJ26: =SUM($O26:$Z26) -> 105409.35 | AK26: =AVERAGE(AE26,AJ26)/AVERAGE($AE$58,$AJ$58) -> 0.1547349
B27: Large Hotels
B28: # of New Hotels | C28: =SUMIFS(Formatting!$A$43:$A$47,Formatting!$E$43:$E$47,'Cash flow forecast'!C$5) -> 1 | D28: =SUMIFS(Formatting!$A$43:$A$47,Formatting!$E$43:$E$47,'Cash flow forecast'!D$5) -> 0 | E28: =SUMIFS(Formatting!$A$43:$A$47,Formatting!$E$43:$E$47,'Cash flow forecast'!E$5) -> 1 | F28: =SUMIFS(Formatting!$A$43:$A$47,Formatting!$E$43:$E$47,'Cash flow forecast'!F$5) -> 0 | G28: =SUMIFS(Formatting!$A$43:$A$47,Formatting!$E$43:$E$47,'Cash flow forecast'!G$5) -> 0 | H28: =SUMIFS(Formatting!$A$43:$A$47,Formatting!$E$43:$E$47,'Cash flow forecast'!H$5) -> 0 | I28: =SUMIFS(Formatting!$A$43:$A$47,Formatting!$E$43:$E$47,'Cash flow forecast'!I$5) -> 0 | J28: =SUMIFS(Formatting!$A$43:$A$47,Formatting!$E$43:$E$47,'Cash flow forecast'!J$5) -> 0 | ... Z28: =SUMIFS(Formatting!$A$43:$A$47,Formatting!$E$43:$E$47,'Cash flow forecast'!Z$5) -> 0
B29: # of Renew Orders | C29: =IFERROR(INDEX(Formatting!$F$44:$T$44,MATCH('Cash flow forecast'!C$5,Formatting!$F$43:$T$43,0)),0)+IFERROR(INDEX(Formatting!$F$46:$T$46,MATCH('Cash flow forecast'!C$5,Formatting!$F$45:$T$45,0)),0)+IFERROR(INDEX(Formatting!$F$48:$T$48,MATCH('Cash flow forecast'!C$5,Formatting!$F$47:$T$47,0)),0) -> 0 | D29: =IFERROR(INDEX(Formatting!$F$44:$T$44,MATCH('Cash flow forecast'!D$5,Formatting!$F$43:$T$43,0)),0)+IFERROR(INDEX(Formatting!$F$46:$T$46,MATCH('Cash flow forecast'!D$5,Formatting!$F$45:$T$45,0)),0)+IFERROR(INDEX(Formatting!$F$48:$T$48,MATCH('Cash flow forecast'!D$5,Formatting!$F$47:$T$47,0)),0) -> 0 | E29: =IFERROR(INDEX(Formatting!$F$44:$T$44,MATCH('Cash flow forecast'!E$5,Formatting!$F$43:$T$43,0)),0)+IFERROR(INDEX(Formatting!$F$46:$T$46,MATCH('Cash flow forecast'!E$5,Formatting!$F$45:$T$45,0)),0)+IFERROR(INDEX(Formatting!$F$48:$T$48,MATCH('Cash flow forecast'!E$5,Formatting!$F$47:$T$47,0)),0) -> 0 | F29: =IFERROR(INDEX(Formatting!$F$44:$T$44,MATCH('Cash flow forecast'!F$5,Formatting!$F$43:$T$43,0)),0)+IFERROR(INDEX(Formatting!$F$46:$T$46,MATCH('Cash flow forecast'!F$5,Formatting!$F$45:$T$45,0)),0)+IFERROR(INDEX(Formatting!$F$48:$T$48,MATCH('Cash flow forecast'!F$5,Formatting!$F$47:$T$47,0)),0) -> 0 | G29: =IFERROR(INDEX(Formatting!$F$44:$T$44,MATCH('Cash flow forecast'!G$5,Formatting!$F$43:$T$43,0)),0)+IFERROR(INDEX(Formatting!$F$46:$T$46,MATCH('Cash flow forecast'!G$5,Formatting!$F$45:$T$45,0)),0)+IFERROR(INDEX(Formatting!$F$48:$T$48,MATCH('Cash flow forecast'!G$5,Formatting!$F$47:$T$47,0)),0) -> 0 | H29: =IFERROR(INDEX(Formatting!$F$44:$T$44,MATCH('Cash flow forecast'!H$5,Formatting!$F$43:$T$43,0)),0)+IFERROR(INDEX(Formatting!$F$46:$T$46,MATCH('Cash flow forecast'!H$5,Formatting!$F$45:$T$45,0)),0)+IFERROR(INDEX(Formatting!$F$48:$T$48,MATCH('Cash flow forecast'!H$5,Formatting!$F$47:$T$47,0)),0) -> 0 | I29: =IFERROR(INDEX(Formatting!$F$44:$T$44,MATCH('Cash flow forecast'!I$5,Formatting!$F$43:$T$43,0)),0)+IFERROR(INDEX(Formatting!$F$46:$T$46,MATCH('Cash flow forecast'!I$5,Formatting!$F$45:$T$45,0)),0)+IFERROR(INDEX(Formatting!$F$48:$T$48,MATCH('Cash flow forecast'!I$5,Formatting!$F$47:$T$47,0)),0) -> 1 | J29: =IFERROR(INDEX(Formatting!$F$44:$T$44,MATCH('Cash flow forecast'!J$5,Formatting!$F$43:$T$43,0)),0)+IFERROR(INDEX(Formatting!$F$46:$T$46,MATCH('Cash flow forecast'!J$5,Formatting!$F$45:$T$45,0)),0)+IFERROR(INDEX(Formatting!$F$48:$T$48,MATCH('Cash flow forecast'!J$5,Formatting!$F$47:$T$47,0)),0) -> 0 | ... Z29: =IFERROR(INDEX(Formatting!$F$44:$T$44,MATCH('Cash flow forecast'!Z$5,Formatting!$F$43:$T$43,0)),0)+IFERROR(INDEX(Formatting!$F$46:$T$46,MATCH('Cash flow forecast'!Z$5,Formatting!$F$45:$T$45,0)),0)+IFERROR(INDEX(Formatting!$F$48:$T$48,MATCH('Cash flow forecast'!Z$5,Formatting!$F$47:$T$47,0)),0) -> 0
B30: Twin Package Orders | C30: =((INDEX(Assumptions!$B$8:$B$46,MATCH("Total Twin",Assumptions!$A$8:$A$46,0)))*((C$28+C$29)*INDEX(Assumptions!$E$96:$E$101,MATCH('Cash flow forecast'!$B30,Assumptions!$A$96:$A$101,0)))) -> 2055.375 | D30: =(((INDEX(Assumptions!$B$8:$B$46,MATCH("Total Twin",Assumptions!$A$8:$A$46,0)))*((D$28+D$29)*INDEX(Assumptions!$E$96:$E$101,MATCH('Cash flow forecast'!$B30,Assumptions!$A$96:$A$101,0))))*(1+Assumptions!$B$103)) -> 0 | E30: =(((INDEX(Assumptions!$B$8:$B$46,MATCH("Total Twin",Assumptions!$A$8:$A$46,0)))*((E$28+E$29)*INDEX(Assumptions!$E$96:$E$101,MATCH('Cash flow forecast'!$B30,Assumptions!$A$96:$A$101,0))))*(1+Assumptions!$B$103)) -> 1849.8375 | F30: =(((INDEX(Assumptions!$B$8:$B$46,MATCH("Total Twin",Assumptions!$A$8:$A$46,0)))*((F$28+F$29)*INDEX(Assumptions!$E$96:$E$101,MATCH('Cash flow forecast'!$B30,Assumptions!$A$96:$A$101,0))))*(1+Assumptions!$B$103)) -> 0 | G30: =(((INDEX(Assumptions!$B$8:$B$46,MATCH("Total Twin",Assumptions!$A$8:$A$46,0)))*((G$28+G$29)*INDEX(Assumptions!$E$96:$E$101,MATCH('Cash flow forecast'!$B30,Assumptions!$A$96:$A$101,0))))*(1+Assumptions!$B$103)) -> 0 | H30: =(((INDEX(Assumptions!$B$8:$B$46,MATCH("Total Twin",Assumptions!$A$8:$A$46,0)))*((H$28+H$29)*INDEX(Assumptions!$E$96:$E$101,MATCH('Cash flow forecast'!$B30,Assumptions!$A$96:$A$101,0))))*(1+Assumptions!$B$103)) -> 0 | I30: =(((INDEX(Assumptions!$B$8:$B$46,MATCH("Total Twin",Assumptions!$A$8:$A$46,0)))*((I$28+I$29)*INDEX(Assumptions!$E$96:$E$101,MATCH('Cash flow forecast'!$B30,Assumptions!$A$96:$A$101,0))))*(1+Assumptions!$B$103)) -> 1849.8375 | J30: =(((INDEX(Assumptions!$B$8:$B$46,MATCH("Total Twin",Assumptions!$A$8:$A$46,0)))*((J$28+J$29)*INDEX(Assumptions!$E$96:$E$101,MATCH('Cash flow forecast'!$B30,Assumptions!$A$96:$A$101,0))))*(1+Assumptions!$B$103)) -> 0 | K30: =(((INDEX(Assumptions!$B$8:$B$46,MATCH("Total Twin",Assumptions!$A$8:$A$46,0)))*((K$28+K$29)*INDEX(Assumptions!$E$96:$E$101,MATCH('Cash flow forecast'!$B30,Assumptions!$A$96:$A$101,0))))*(1+Assumptions!$B$103)) -> 1849.8375 | ... Z30: =(((INDEX(Assumptions!$B$8:$B$46,MATCH("Total Twin",Assumptions!$A$8:$A$46,0)))*((Z$28+Z$29)*INDEX(Assumptions!$E$96:$E$101,MATCH('Cash flow forecast'!$B30,Assumptions!$A$96:$A$101,0))))*(1+Assumptions!$B$103)) -> 0 | AA30: =SUMIFS($C30:$N30,$C$6:$N$6,AA$5) -> 2055.375 | AB30: =SUMIFS($C30:$N30,$C$6:$N$6,AB$5) -> 1849.8375 | AC30: =SUMIFS($C30:$N30,$C$6:$N$6,AC$5) -> 1849.8375 | AD30: =SUMIFS($C30:$N30,$C$6:$N$6,AD$5) -> 1849.8375 | AE30: =SUM($C30:$N30) -> 7604.8875 | AF30: =SUMIFS($O30:$Z30,$O$6:$Z$6,AF$5) -> 1849.8375 | AG30: =SUMIFS($O30:$Z30,$O$6:$Z$6,AG$5) -> 1849.8375 | AH30: =SUMIFS($O30:$Z30,$O$6:$Z$6,AH$5) -> 1849.8375 | AI30: =SUMIFS($O30:$Z30,$O$6:$Z$6,AI$5) -> 3699.675 | AJ30: =SUM($O30:$Z30) -> 9249.1875 | AK30: =AVERAGE(AE30,AJ30)/AVERAGE($AE$58,$AJ$58) -> 0.012200952
B31: Full Package Orders | C31: =((INDEX(Assumptions!$B$8:$B$46,MATCH("Total Full",Assumptions!$A$8:$A$46,0)))*((C$28+C$29)*INDEX(Assumptions!$E$96:$E$101,MATCH('Cash flow forecast'!$B31,Assumptions!$A$96:$A$101,0)))) -> 0 | D31: =(((INDEX(Assumptions!$B$8:$B$46,MATCH("Total Full",Assumptions!$A$8:$A$46,0)))*((D$28+D$29)*INDEX(Assumptions!$E$96:$E$101,MATCH('Cash flow forecast'!$B31,Assumptions!$A$96:$A$101,0)))))*(1+Assumptions!$B$103) -> 0 | E31: =(((INDEX(Assumptions!$B$8:$B$46,MATCH("Total Full",Assumptions!$A$8:$A$46,0)))*((E$28+E$29)*INDEX(Assumptions!$E$96:$E$101,MATCH('Cash flow forecast'!$B31,Assumptions!$A$96:$A$101,0)))))*(1+Assumptions!$B$103) -> 0 | F31: =(((INDEX(Assumptions!$B$8:$B$46,MATCH("Total Full",Assumptions!$A$8:$A$46,0)))*((F$28+F$29)*INDEX(Assumptions!$E$96:$E$101,MATCH('Cash flow forecast'!$B31,Assumptions!$A$96:$A$101,0)))))*(1+Assumptions!$B$103) -> 0 | G31: =(((INDEX(Assumptions!$B$8:$B$46,MATCH("Total Full",Assumptions!$A$8:$A$46,0)))*((G$28+G$29)*INDEX(Assumptions!$E$96:$E$101,MATCH('Cash flow forecast'!$B31,Assumptions!$A$96:$A$101,0)))))*(1+Assumptions!$B$103) -> 0 | H31: =(((INDEX(Assumptions!$B$8:$B$46,MATCH("Total Full",Assumptions!$A$8:$A$46,0)))*((H$28+H$29)*INDEX(Assumptions!$E$96:$E$101,MATCH('Cash flow forecast'!$B31,Assumptions!$A$96:$A$101,0)))))*(1+Assumptions!$B$103) -> 0 | I31: =(((INDEX(Assumptions!$B$8:$B$46,MATCH("Total Full",Assumptions!$A$8:$A$46,0)))*((I$28+I$29)*INDEX(Assumptions!$E$96:$E$101,MATCH('Cash flow forecast'!$B31,Assumptions!$A$96:$A$101,0)))))*(1+Assumptions!$B$103) -> 0 | J31: =(((INDEX(Assumptions!$B$8:$B$46,MATCH("Total Full",Assumptions!$A$8:$A$46,0)))*((J$28+J$29)*INDEX(Assumptions!$E$96:$E$101,MATCH('Cash flow forecast'!$B31,Assumptions!$A$96:$A$101,0)))))*(1+Assumptions!$B$103) -> 0 | K31: =(((INDEX(Assumptions!$B$8:$B$46,MATCH("Total Full",Assumptions!$A$8:$A$46,0)))*((K$28+K$29)*INDEX(Assumptions!$E$96:$E$101,MATCH('Cash flow forecast'!$B31,Assumptions!$A$96:$A$101,0)))))*(1+Assumptions!$B$103) -> 0 | ... Z31: =(((INDEX(Assumptions!$B$8:$B$46,MATCH("Total Full",Assumptions!$A$8:$A$46,0)))*((Z$28+Z$29)*INDEX(Assumptions!$E$96:$E$101,MATCH('Cash flow forecast'!$B31,Assumptions!$A$96:$A$101,0)))))*(1+Assumptions!$B$103) -> 0 | AA31: =SUMIFS($C31:$N31,$C$6:$N$6,AA$5) -> 0 | AB31: =SUMIFS($C31:$N31,$C$6:$N$6,AB$5) -> 0 | AC31: =SUMIFS($C31:$N31,$C$6:$N$6,AC$5) -> 0 | AD31: =SUMIFS($C31:$N31,$C$6:$N$6,AD$5) -> 0 | AE31: =SUM($C31:$N31) -> 0 | AF31: =SUMIFS($O31:$Z31,$O$6:$Z$6,AF$5) -> 0 | AG31: =SUMIFS($O31:$Z31,$O$6:$Z$6,AG$5) -> 0 | AH31: =SUMIFS($O31:$Z31,$O$6:$Z$6,AH$5) -> 0 | AI31: =SUMIFS($O31:$Z31,$O$6:$Z$6,AI$5) -> 0 | AJ31: =SUM($O31:$Z31) -> 0 | AK31: =AVERAGE(AE31,AJ31)/AVERAGE($AE$58,$AJ$58) -> 0
B32: Queen Package Orders | C32: =((INDEX(Assumptions!$B$8:$B$46,MATCH("Total Queen",Assumptions!$A$8:$A$46,0)))*((C$28+C$29)*INDEX(Assumptions!$E$96:$E$101,MATCH('Cash flow forecast'!$B32,Assumptions!$A$96:$A$101,0)))) -> 23400 | D32: =(((INDEX(Assumptions!$B$8:$B$46,MATCH("Total Queen",Assumptions!$A$8:$A$46,0)))*((D$28+D$29)*INDEX(Assumptions!$E$96:$E$101,MATCH('Cash flow forecast'!$B32,Assumptions!$A$96:$A$101,0)))))*(1+Assumptions!$B$103) -> 0 | E32: =(((INDEX(Assumptions!$B$8:$B$46,MATCH("Total Queen",Assumptions!$A$8:$A$46,0)))*((E$28+E$29)*INDEX(Assumptions!$E$96:$E$101,MATCH('Cash flow forecast'!$B32,Assumptions!$A$96:$A$101,0)))))*(1+Assumptions!$B$103) -> 21060 | F32: =(((INDEX(Assumptions!$B$8:$B$46,MATCH("Total Queen",Assumptions!$A$8:$A$46,0)))*((F$28+F$29)*INDEX(Assumptions!$E$96:$E$101,MATCH('Cash flow forecast'!$B32,Assumptions!$A$96:$A$101,0)))))*(1+Assumptions!$B$103) -> 0 | G32: =(((INDEX(Assumptions!$B$8:$B$46,MATCH("Total Queen",Assumptions!$A$8:$A$46,0)))*((G$28+G$29)*INDEX(Assumptions!$E$96:$E$101,MATCH('Cash flow forecast'!$B32,Assumptions!$A$96:$A$101,0)))))*(1+Assumptions!$B$103) -> 0 | H32: =(((INDEX(Assumptions!$B$8:$B$46,MATCH("Total Queen",Assumptions!$A$8:$A$46,0)))*((H$28+H$29)*INDEX(Assumptions!$E$96:$E$101,MATCH('Cash flow forecast'!$B32,Assumptions!$A$96:$A$101,0)))))*(1+Assumptions!$B$103) -> 0 | I32: =(((INDEX(Assumptions!$B$8:$B$46,MATCH("Total Queen",Assumptions!$A$8:$A$46,0)))*((I$28+I$29)*INDEX(Assumptions!$E$96:$E$101,MATCH('Cash flow forecast'!$B32,Assumptions!$A$96:$A$101,0)))))*(1+Assumptions!$B$103) -> 21060 | J32: =(((INDEX(Assumptions!$B$8:$B$46,MATCH("Total Queen",Assumptions!$A$8:$A$46,0)))*((J$28+J$29)*INDEX(Assumptions!$E$96:$E$101,MATCH('Cash flow forecast'!$B32,Assumptions!$A$96:$A$101,0)))))*(1+Assumptions!$B$103) -> 0 | K32: =(((INDEX(Assumptions!$B$8:$B$46,MATCH("Total Queen",Assumptions!$A$8:$A$46,0)))*((K$28+K$29)*INDEX(Assumptions!$E$96:$E$101,MATCH('Cash flow forecast'!$B32,Assumptions!$A$96:$A$101,0)))))*(1+Assumptions!$B$103) -> 21060 | ... Z32: =(((INDEX(Assumptions!$B$8:$B$46,MATCH("Total Queen",Assumptions!$A$8:$A$46,0)))*((Z$28+Z$29)*INDEX(Assumptions!$E$96:$E$101,MATCH('Cash flow forecast'!$B32,Assumptions!$A$96:$A$101,0)))))*(1+Assumptions!$B$103) -> 0 | AA32: =SUMIFS($C32:$N32,$C$6:$N$6,AA$5) -> 23400 | AB32: =SUMIFS($C32:$N32,$C$6:$N$6,AB$5) -> 21060 | AC32: =SUMIFS($C32:$N32,$C$6:$N$6,AC$5) -> 21060 | AD32: =SUMIFS($C32:$N32,$C$6:$N$6,AD$5) -> 21060 | AE32: =SUM($C32:$N32) -> 86580 | AF32: =SUMIFS($O32:$Z32,$O$6:$Z$6,AF$5) -> 21060 | AG32: =SUMIFS($O32:$Z32,$O$6:$Z$6,AG$5) -> 21060 | AH32: =SUMIFS($O32:$Z32,$O$6:$Z$6,AH$5) -> 21060 | AI32: =SUMIFS($O32:$Z32,$O$6:$Z$6,AI$5) -> 42120 | AJ32: =SUM($O32:$Z32) -> 105300 | AK32: =AVERAGE(AE32,AJ32)/AVERAGE($AE$58,$AJ$58) -> 0.1389052
B33: King Package Orders | C33: =((INDEX(Assumptions!$B$8:$B$46,MATCH("Total King",Assumptions!$A$8:$A$46,0)))*((C$28+C$29)*INDEX(Assumptions!$E$96:$E$101,MATCH('Cash flow forecast'!$B33,Assumptions!$A$96:$A$101,0)))) -> 3825 | D33: =(((INDEX(Assumptions!$B$8:$B$46,MATCH("Total King",Assumptions!$A$8:$A$46,0)))*((D$28+D$29)*INDEX(Assumptions!$E$96:$E$101,MATCH('Cash flow forecast'!$B33,Assumptions!$A$96:$A$101,0)))))*(1+Assumptions!$B$103) -> 0 | E33: =(((INDEX(Assumptions!$B$8:$B$46,MATCH("Total King",Assumptions!$A$8:$A$46,0)))*((E$28+E$29)*INDEX(Assumptions!$E$96:$E$101,MATCH('Cash flow forecast'!$B33,Assumptions!$A$96:$A$101,0)))))*(1+Assumptions!$B$103) -> 3442.5 | F33: =(((INDEX(Assumptions!$B$8:$B$46,MATCH("Total King",Assumptions!$A$8:$A$46,0)))*((F$28+F$29)*INDEX(Assumptions!$E$96:$E$101,MATCH('Cash flow forecast'!$B33,Assumptions!$A$96:$A$101,0)))))*(1+Assumptions!$B$103) -> 0 | G33: =(((INDEX(Assumptions!$B$8:$B$46,MATCH("Total King",Assumptions!$A$8:$A$46,0)))*((G$28+G$29)*INDEX(Assumptions!$E$96:$E$101,MATCH('Cash flow forecast'!$B33,Assumptions!$A$96:$A$101,0)))))*(1+Assumptions!$B$103) -> 0 | H33: =(((INDEX(Assumptions!$B$8:$B$46,MATCH("Total King",Assumptions!$A$8:$A$46,0)))*((H$28+H$29)*INDEX(Assumptions!$E$96:$E$101,MATCH('Cash flow forecast'!$B33,Assumptions!$A$96:$A$101,0)))))*(1+Assumptions!$B$103) -> 0 | I33: =(((INDEX(Assumptions!$B$8:$B$46,MATCH("Total King",Assumptions!$A$8:$A$46,0)))*((I$28+I$29)*INDEX(Assumptions!$E$96:$E$101,MATCH('Cash flow forecast'!$B33,Assumptions!$A$96:$A$101,0)))))*(1+Assumptions!$B$103) -> 3442.5 | J33: =(((INDEX(Assumptions!$B$8:$B$46,MATCH("Total King",Assumptions!$A$8:$A$46,0)))*((J$28+J$29)*INDEX(Assumptions!$E$96:$E$101,MATCH('Cash flow forecast'!$B33,Assumptions!$A$96:$A$101,0)))))*(1+Assumptions!$B$103) -> 0 | K33: =(((INDEX(Assumptions!$B$8:$B$46,MATCH("Total King",Assumptions!$A$8:$A$46,0)))*((K$28+K$29)*INDEX(Assumptions!$E$96:$E$101,MATCH('Cash flow forecast'!$B33,Assumptions!$A$96:$A$101,0)))))*(1+Assumptions!$B$103) -> 3442.5 | ... Z33: =(((INDEX(Assumptions!$B$8:$B$46,MATCH("Total King",Assumptions!$A$8:$A$46,0)))*((Z$28+Z$29)*INDEX(Assumptions!$E$96:$E$101,MATCH('Cash flow forecast'!$B33,Assumptions!$A$96:$A$101,0)))))*(1+Assumptions!$B$103) -> 0 | AA33: =SUMIFS($C33:$N33,$C$6:$N$6,AA$5) -> 3825 | AB33: =SUMIFS($C33:$N33,$C$6:$N$6,AB$5) -> 3442.5 | AC33: =SUMIFS($C33:$N33,$C$6:$N$6,AC$5) -> 3442.5 | AD33: =SUMIFS($C33:$N33,$C$6:$N$6,AD$5) -> 3442.5 | AE33: =SUM($C33:$N33) -> 14152.5 | AF33: =SUMIFS($O33:$Z33,$O$6:$Z$6,AF$5) -> 3442.5 | AG33: =SUMIFS($O33:$Z33,$O$6:$Z$6,AG$5) -> 3442.5 | AH33: =SUMIFS($O33:$Z33,$O$6:$Z$6,AH$5) -> 3442.5 | AI33: =SUMIFS($O33:$Z33,$O$6:$Z$6,AI$5) -> 6885 | AJ33: =SUM($O33:$Z33) -> 17212.5 | AK33: =AVERAGE(AE33,AJ33)/AVERAGE($AE$58,$AJ$58) -> 0.022705657
